Workbook
Name DD: 'Данные ВВ'!$A$1:$H$58
Name В: 'Данные ВВ'!$B$3:$B$58
Name ВВ: 'Данные ВВ'!$B$3:$B$58
Name Дт: 'Наст. эксц.'!$N$5:$N$50
Name УПС.09.УВ2_105: 'Карта настройки'!$Q$17

Sheet Карта н. для ц.
I1: КАРТА НАСТРОЙКИ
K3: Прокат профильной трубы Ø | L3: =Осн.таблица!A2 -> 250 | M3: мм
H4: из заготовки Ø | I4: =Осн.таблица!C3 -> 245.77055 | J4: толщина стенки | L4: =Осн.таблица!A19 -> 8 | M4: мм
D6: Настройка горизонтальных валков | M6: Настройка эджеров
A7: =NOW() -> 46288.744
A8: Клеть | B8: Валок горизонтальный | E8: Высота калибра /обжатия | G8: База | H8: Наборка на кассете | J8: Валок вертикальный | M8: Диаметр | N8: Ширина бочки | O8: Втулка дист. | P8: Ширина кал-ра/обж | R8: Наб. прок.
A9: =Осн.таблица!D2 -> Кл.1 | B9: ='Карта настройки'!H17 -> 1 | C9: =Осн.таблица!D10 -> 400 | D9: =Осн.таблица!D8 -> 529 | E9: =Осн.таблица!D5 -> 240.77055 | F9: =Осн.таблица!D3 -> 5 | G9: =Осн.таблица!D32 -> 41.114727 | H9: =Осн.таблица!D31 -> 99.885273 | J9: ='Карта настройки'!Q17 -> УПС.09.УВ2И-105 | M9: =Осн.таблица!D18 -> 410 | N9: =Осн.таблица!A13 -> 105 | O9: =Осн.таблица!D33 -> 27.5 | P9: =Осн.таблица!D15 -> 250.77055 | Q9: =Осн.таблица!D14 -> -5 | R9: ='Карта настройки'!AA17 -> 114.61473
A10: =Осн.таблица!E2 -> Кл.2 | B10: ='Карта настройки'!H18 -> 3 | C10: =Осн.таблица!E10 -> 400 | D10: =Осн.таблица!E8 -> 548 | E10: =Осн.таблица!E5 -> 227.77055 | F10: =Осн.таблица!E3 -> 13 | G10: =Осн.таблица!E32 -> 38.114727 | H10: =Осн.таблица!E31 -> 102.88527 | J10: ='Карта настройки'!Q18 -> УПС.09.УВ3И-115 | M10: =Осн.таблица!E18 -> 410 | N10: =Осн.таблица!A14 -> 115 | O10: =Осн.таблица!E33 -> 22.5 | P10: =Осн.таблица!E15 -> 243.77055 | Q10: =Осн.таблица!E14 -> 7 | R10: ='Карта настройки'!AA18 -> 118.11473
A11: =Осн.таблица!F2 -> Кл.3 | B11: ='Карта настройки'!H19 -> 4 | C11: =Осн.таблица!F10 -> 400 | D11: =Осн.таблица!F8 -> 565 | E11: =Осн.таблица!F5 -> 225.77055 | F11: =Осн.таблица!F3 -> 2 | G11: =Осн.таблица!F32 -> 30.614727 | H11: =Осн.таблица!F31 -> 110.38527 | J11: ='Карта настройки'!Q19 -> УПС.09.УВ3И-125 | M11: =Осн.таблица!F18 -> 410 | N11: =Осн.таблица!A15 -> 125 | O11: =Осн.таблица!F33 -> 17.5 | P11: =Осн.таблица!F15 -> 234.77055 | Q11: =Осн.таблица!F14 -> 9 | R11: ='Карта настройки'!AA19 -> 122.61473
A12: =Осн.таблица!G2 -> Кл.4 | B12: ='Карта настройки'!H20 -> 4 | C12: =Осн.таблица!G10 -> 400 | D12: =Осн.таблица!G8 -> 577 | E12: =Осн.таблица!G5 -> 219.77055 | F12: =Осн.таблица!G3 -> 6 | G12: =Осн.таблица!G32 -> 27.614727 | H12: =Осн.таблица!G31 -> 113.38527 | J12: ='Карта настройки'!Q20 -> УПС.09.УВ4-125 | M12: =Осн.таблица!G18 -> 410 | N12: =Осн.таблица!A16 -> 125 | O12: =Осн.таблица!G33 -> 17.5 | P12: =Осн.таблица!G15 -> 226.77055 | Q12: =Осн.таблица!G14 -> 8 | R12: ='Карта настройки'!AA20 -> 126.61473
A13: =Осн.таблица!H2 -> Кл.5 | B13: ='Карта настройки'!H21 -> 5 | C13: =Осн.таблица!H10 -> 400 | D13: =Осн.таблица!H8 -> 587 | E13: =Осн.таблица!H5 -> 218.77055 | F13: =Осн.таблица!H3 -> 1 | G13: =Осн.таблица!H32 -> 23.114727 | H13: =Осн.таблица!H31 -> 117.88527 | J13: ='Карта настройки'!Q21 -> УПС.09.УВ4И-135 | M13: =Осн.таблица!H18 -> 410 | N13: =Осн.таблица!A17 -> 135 | O13: =Осн.таблица!H33 -> 12.5 | P13: =Осн.таблица!H15 -> 219.77055 | Q13: =Осн.таблица!H14 -> 7 | R13: ='Карта настройки'!AA21 -> 130.11473
A14: =Осн.таблица!I2 -> Кл.6 | B14: ='Карта настройки'!H22 -> 5 | C14: =Осн.таблица!I10 -> 400 | D14: =Осн.таблица!I8 -> 589 | E14: =Осн.таблица!I5 -> 216.77055 | F14: =Осн.таблица!I3 -> 2 | G14: =Осн.таблица!I32 -> 23.114727 | H14: =Осн.таблица!I31 -> 117.88527 | J14: ='Карта настройки'!Q22 -> Валок наборной | M14: =Осн.таблица!I18 -> 455 | N14: =Осн.таблица!A18 -> 145 | O14: =Осн.таблица!I33 -> 7.5 | P14: =Осн.таблица!I15 -> 216.77055 | Q14: =Осн.таблица!I14 -> 3 | R14: ='Карта настройки'!AA22 -> 109.11473
D17: Скоростные характеристики стана УПС
A19: Клеть | D19: 1 | E19: 2 | F19: 3 | G19: 4 | H19: 5 | I19: 6
A20: Усл. Тип ГВ | D20: ='Карта настройки'!G17 -> 400 | E20: ='Карта настройки'!G18 -> 400 | F20: ='Карта настройки'!G19 -> 400 | G20: ='Карта настройки'!G20 -> 400 | H20: ='Карта настройки'!G21 -> 400 | I20: 300 | J20: Vгв, м/мин (iкпп= 6,17/3,40)
A21: Диаметр ГВ, мм | D21: ='Карта настройки'!I17 -> 529 | E21: ='Карта настройки'!I18 -> 548 | F21: ='Карта настройки'!I19 -> 565 | G21: ='Карта настройки'!I20 -> 577 | H21: ='Карта настройки'!I21 -> 587 | I21: ='Карта настройки'!I22 -> 589
A22: Коэф. Скорости* | D22: 1 | E22: =1.01*($D$21/E21) -> 0.97498175 | F22: =1.01*($D$21/F21) -> 0.94564602 | G22: =1.01*(0.85*$D$21/G21) -> 0.78708232 | H22: =1.01*($D$21/H21) -> 0.91020443 | I22: =1.01*($D$21/I21) -> 0.90711375
E23: =1.005*($D$21/E21)*(1+(1.015-1)*('Карта настройки'!F18/'Карта настройки'!$F$23)) -> 0.97484941 | F23: =1.005*($D$21/F21)*(1+(1.015-1)*('Карта настройки'!F19/'Карта настройки'!$F$23)) -> 0.94346878 | G23: =1.005*(0.85*$D$21/G21)*(1+(1.015-1)*('Карта настройки'!F20/'Карта настройки'!$F$23)) -> 0.7858386 | H23: =1.005*($D$21/H21)*(1+(1.015-1)*('Карта настройки'!F21/'Карта настройки'!$F$23)) -> 0.90745143 | I23: =1.005*($D$21/I21)*(1+(1.015-1)*('Карта настройки'!F22/'Карта настройки'!$F$23)) -> 0.9034966
A24: Частота оборотов привода, об/мин | D24: 300 | E24: =$D$24*E23 -> 292.45482 | F24: =$D$24*F23 -> 283.04063 | G24: =$D$24*G23 -> 235.75158 | H24: =$D$24*H23 -> 272.23543 | I24: =$D$24*I23 -> 271.04898 | J24: =(3.1415*($I$21/1000)*I24)/(6.17*50) -> 1.6257171 | K24: =(3.1415*($I$21/1000)*I24)/(3.4*50) -> 2.9501983
D25: 600 | E25: =$D$25*E23 -> 584.90965 | F25: =$D$25*F23 -> 566.08127 | G25: =$D$25*G23 -> 471.50316 | H25: =$D$25*H23 -> 544.47086 | I25: =$D$25*I23 -> 542.09796 | J25: =(3.1415*($I$21/1000)*I25)/(6.17*50) -> 3.2514341 | K25: =(3.1415*($I$21/1000)*I25)/(3.4*50) -> 5.9003967
D26: 700 | E26: =$D$26*E23 -> 682.39459 | F26: =$D$26*F23 -> 660.42815 | G26: =$D$26*G23 -> 550.08702 | H26: =$D$26*H23 -> 635.216 | I26: =$D$26*I23 -> 632.44762 | J26: =(3.1415*($I$21/1000)*I26)/(6.17*50) -> 3.7933398 | K26: =(3.1415*($I$21/1000)*I26)/(3.4*50) -> 6.8837961
D27: 800 | E27: =$D$27*E23 -> 779.87953 | F27: =$D$27*F23 -> 754.77503 | G27: =$D$27*G23 -> 628.67088 | H27: =$D$27*H23 -> 725.96115 | I27: =$D$27*I23 -> 722.79728 | J27: =(3.1415*($I$21/1000)*I27)/(6.17*50) -> 4.3352455 | K27: =(3.1415*($I$21/1000)*I27)/(3.4*50) -> 7.8671955
D28: 900 | E28: =$D$28*E23 -> 877.36447 | F28: =$D$28*F23 -> 849.1219 | G28: =$D$28*G23 -> 707.25474 | H28: =$D$28*H23 -> 816.70629 | I28: =$D$28*I23 -> 813.14694 | J28: =(3.1415*($I$21/1000)*I28)/(6.17*50) -> 4.8771512 | K28: =(3.1415*($I$21/1000)*I28)/(3.4*50) -> 8.850595
D29: 1000 | E29: =$D$29*E23 -> 974.84941 | F29: =$D$29*F23 -> 943.46878 | G29: =$D$29*G23 -> 785.8386 | H29: =$D$29*H23 -> 907.45143 | I29: =$D$29*I23 -> 903.4966 | J29: =(3.1415*($I$21/1000)*I29)/(6.17*50) -> 5.4190569 | K29: =(3.1415*($I$21/1000)*I29)/(3.4*50) -> 9.8339944
D30: 1200 | E30: =$D$30*E23 -> 1169.8193 | F30: =$D$30*F23 -> 1132.1625 | G30: =$D$30*G23 -> 943.00632 | H30: =$D$30*H23 -> 1088.9417 | I30: =$D$30*I23 -> 1084.1959 | J30: =(3.1415*($I$21/1000)*I30)/(6.17*50) -> 6.5028683 | K30: =(3.1415*($I$21/1000)*I30)/(3.4*50) -> 11.800793
D31: 1300 | E31: =$D$31*E23 -> 1267.3042 | F31: =$D$31*F23 -> 1226.5094 | G31: =$D$31*G23 -> 1021.5902 | H31: =$D$31*H23 -> 1179.6869 | I31: =$D$31*I23 -> 1174.5456 | J31: =(3.1415*($I$21/1000)*I31)/(6.17*50) -> 7.044774 | K31: =(3.1415*($I$21/1000)*I31)/(3.4*50) -> 12.784193
D32: 1400 | E32: =$D$32*E23 -> 1364.7892 | F32: =$D$32*F23 -> 1320.8563 | G32: =$D$32*G23 -> 1100.174 | H32: =$D$32*H23 -> 1270.432 | I32: =$D$32*I23 -> 1264.8952 | J32: =(3.1415*($I$21/1000)*I32)/(6.17*50) -> 7.5866797 | K32: =(3.1415*($I$21/1000)*I32)/(3.4*50) -> 13.767592
D33: 1500 | E33: =$D$33*E23 -> 1462.2741 | F33: =$D$33*F23 -> 1415.2032 | G33: =$D$33*G23 -> 1178.7579 | H33: =$D$33*H23 -> 1361.1771 | I33: =$D$33*I23 -> 1355.2449 | J33: =(3.1415*($I$21/1000)*I33)/(6.17*50) -> 8.1285854 | K33: =(3.1415*($I$21/1000)*I33)/(3.4*50) -> 14.750992

Sheet Карта настройки
N1: КАРТА НАСТРОЙКИ
N2: (контрольная) | AB2: УТВЕРЖДАЮ
AB3: Директор
A4: =NOW() -> 46288.744
J6: Прокат профильной трубы | K6: 250 | L6: х | M6: 160 | N6: х | O6: 8 | P6: толщина стенки | W6: из заготовки Ø | X6: =Осн.таблица!C3 -> 245.77055 | Y6: мм
I8: Подбор диаметра заготовки ограничен: | J8: от | K8: =((K6+M6)/2)*W12 -> 250.06941 | L8: до | M8: =((K6+M6)/2)*Y12 -> 255.41 | O8: =Осн.таблица!C13 -> 3.875 | P8: отношение Rn/s | W8: выбор по списку Øз | X8: 0 | Y8: мм
J10: Подбор радиуса закругления | K10: 31 | L10: мм | M10: =Осн.таблица!C7 -> 33.709888 | N10: =100-((K10*100)/M10) -> 8.0388529 | O10: =M10/O6 -> 4.213736 | W10: введите количество работающих клетей | X10: 5 | Y10: (иск. Кл1)
J12: Расчётный радиус закругления | K12: =((2*(K6+M6)-(PI()*X6*(1-(0.005+0.0025*O6))))/1.77) -> 37.961485 | L12: мм | P12: коэффициенты отношения Øз/а* | V12: min | W12: =Коэф!G5 -> 1.2198508 | X12: max | Y12: =Коэф!F5 -> 1.2459024 | Z12: реал | AA12: =X6/((K6+M6)/2) -> 1.1988807
A13: Настройка горизонтальных валков | Q13: Настройка эджеров
A15: Кл | B15: Рп, т | C15: Мп, кгм | D15: Сумарные обжатия | G15: Валок горизонтальный | K15: Высота калибра | O15: Шайбы | Q15: Валок вертикальный | T15: Кас. | U15: Dвв | V15: А | X15: Lв и Rв вертикального валка | AA15: Наб. под опоры ВВ | AB15: Втулка дист. | AC15: Ширина
A16: № | D16: ГВ | E16: ВВ | F16: Σ | G16: Lг | H16: №Г | I16: Dг | J16: Rг | K16: В | L16: Обж | N16: Пер | O16: База | P16: Кас. | Q16: Наименование | T16: В | V16: max | W16: min | X16: Lв | Y16: Rв | Z16: Δщ | AC16: кал | AD16: обж
A17: 1 | B17: =Осн.таблица!D36 -> 19.870124 | C17: =Осн.таблица!D37 -> 46.745583 | D17: =IF(L17<=0,0,L17) -> 5 | E17: =AD17 -> -5 | F17: =IF(E17<0,D17+(D17+E17),D17+E17) -> 5 | G17: 400 | H17: =VLOOKUP(I17,'Данные ВГ'!A:B,2) -> 1 | I17: 529 | J17: 300 | K17: =Осн.таблица!D5 -> 240.77055 | L17: 5 | O17: =Осн.таблица!D32 -> 41.114727 | P17: =Осн.таблица!D31 -> 99.885273 | Q17: УПС.09.УВ2И-105 | U17: 410 | V17: =IF(T17=0,VLOOKUP(U17,'Наст. эксц.'!$B$21:$C$30,2),VLOOKUP(U17,'Наст. эксц.'!$H$21:$I$30,2)) -> 500 | W17: =VLOOKUP(U17,'Наст. эксц.'!D21:E30,2) -> 140 | X17: 105 | Y17: 300 | Z17: =Осн.таблица!D4 -> 164.37734 | AA17: =IF($T$17=0,570-(125+(AC17+U17)/2),0) -> 114.61473 | AB17: =Осн.таблица!D33 -> 27.5 | AC17: =Осн.таблица!D15 -> 250.77055 | AD17: -5
A18: 2 | B18: =Осн.таблица!E36 -> 37.779622 | C18: =Осн.таблица!E37 -> 945.34648 | D18: =IF(L18<=0,0,L18) -> 13 | E18: =AD18 -> 7 | F18: =IF(E18<0,D18+(D18+E18),D18+E18) -> 20 | G18: 400 | H18: =VLOOKUP(I18,'Данные ВГ'!A:B,2) -> 3 | I18: 548 | J18: 600 | K18: =Осн.таблица!E5 -> 227.77055 | L18: =Осн.таблица!E3 -> 13 | N18: -6 | O18: =Осн.таблица!E32 -> 38.114727 | P18: =Осн.таблица!E31 -> 102.88527 | Q18: УПС.09.УВ3И-115 | T18: 220 | U18: 410 | V18: =IF(T17=0,VLOOKUP(U18,'Наст. эксц.'!$B$21:$C$30,2),VLOOKUP(U18,'Наст. эксц.'!$H$21:$I$30,2)) -> 500 | W18: =VLOOKUP(U18,'Наст. эксц.'!D21:E30,2) -> 140 | X18: 115 | Y18: 600 | Z18: =Осн.таблица!E4 -> 193.45597 | AA18: =IF($T$17=0,570-(125+(AC18+U18)/2),0) -> 118.11473 | AB18: =Осн.таблица!E33 -> 22.5 | AC18: =Осн.таблица!E15 -> 243.77055 | AD18: 7
A19: 3 | B19: =Осн.таблица!F36 -> 15.352502 | C19: =Осн.таблица!F37 -> 956.07061 | D19: =L19 -> 2 | E19: =AD19 -> 9 | F19: =IF(E19<0,D19+(D19+E19),D19+E19) -> 11 | G19: 400 | H19: =VLOOKUP(I19,'Данные ВГ'!A:B,2) -> 4 | I19: 565 | J19: 1200 | K19: =Осн.таблица!F5 -> 225.77055 | L19: 2 | O19: =Осн.таблица!F32 -> 30.614727 | P19: =Осн.таблица!F31 -> 110.38527 | Q19: УПС.09.УВ3И-125 | U19: 410 | V19: =IF(T19=0,VLOOKUP(U19,'Наст. эксц.'!$B$21:$C$30,2),VLOOKUP(U19,'Наст. эксц.'!$H$21:$I$30,2)) -> 500 | W19: =VLOOKUP(U19,'Наст. эксц.'!D21:E30,2) -> 140 | X19: 125 | Y19: 600 | Z19: =Осн.таблица!F4 -> 208.9865 | AA19: =IF($T$19=0,570-(125+(AC19+U19)/2),0) -> 122.61473 | AB19: =Осн.таблица!F33 -> 17.5 | AC19: =Осн.таблица!F15 -> 234.77055 | AD19: 9
A20: 4 | B20: =Осн.таблица!G36 -> 28.491482 | C20: =Осн.таблица!G37 -> 1003.983 | D20: =L20 -> 6 | E20: =AD20 -> 8 | F20: =IF(E20<0,D20+(D20+E20),D20+E20) -> 14 | G20: 400 | H20: =VLOOKUP(I20,'Данные ВГ'!A:B,2) -> 4 | I20: 577 | J20: 3000 | K20: =Осн.таблица!G5 -> 219.77055 | L20: =Осн.таблица!G3 -> 6 | N20: -6 | O20: =Осн.таблица!G32 -> 27.614727 | P20: =Осн.таблица!G31 -> 113.38527 | Q20: УПС.09.УВ4-125 | T20: 220 | U20: 410 | V20: =IF(T19=0,VLOOKUP(U20,'Наст. эксц.'!$B$21:$C$30,2),VLOOKUP(U20,'Наст. эксц.'!$H$21:$I$30,2)) -> 500 | W20: =VLOOKUP(U20,'Наст. эксц.'!D21:E30,2) -> 140 | X20: 125 | Y20: 1500 | Z20: =Осн.таблица!G4 -> 213.09646 | AA20: =IF($T$19=0,570-(125+(AC20+U20)/2),0) -> 126.61473 | AB20: =Осн.таблица!G33 -> 17.5 | AC20: =Осн.таблица!G15 -> 226.77055 | AD20: 8
A21: 5 | B21: =Осн.таблица!H36 -> 11.839366 | C21: =Осн.таблица!H37 -> 1013.5261 | D21: =L21 -> 1 | E21: =AD21 -> 7 | F21: =IF(E21<0,D21+(D21+E21),D21+E21) -> 8 | G21: 400 | H21: =VLOOKUP(I21,'Данные ВГ'!A:B,2) -> 5 | I21: 587 | J21: 7000 | K21: =Осн.таблица!H5 -> 218.77055 | L21: 1 | O21: =Осн.таблица!H32 -> 23.114727 | P21: =Осн.таблица!H31 -> 117.88527 | Q21: УПС.09.УВ4И-135 | U21: 410 | V21: =IF(T21=0,VLOOKUP(U21,'Наст. эксц.'!$B$21:$C$30,2),VLOOKUP(U21,'Наст. эксц.'!$H$21:$I$30,2)) -> 500 | W21: =VLOOKUP(U21,'Наст. эксц.'!D22:E31,2) -> 140 | X21: 135 | Y21: 1500 | Z21: =Осн.таблица!H4 -> 215.91282 | AA21: =IF($T$21=0,570-(125+(AC21+U21)/2),0) -> 130.11473 | AB21: =Осн.таблица!H33 -> 12.5 | AC21: =Осн.таблица!H15 -> 219.77055 | AD21: 7
A22: 6 | B22: =Осн.таблица!I36 -> 17.08566 | C22: =Осн.таблица!I37 -> 1020.8272 | D22: =L22 -> 1 | E22: =AD22 -> 3 | F22: =IF(E22<0,D22+(D22+E22),D22+E22) -> 4 | G22: 400 | H22: =VLOOKUP(I22,'Данные ВГ'!A:B,2) -> 5 | I22: 589 | J22: ― | K22: =Осн.таблица!I5 -> 216.77055 | L22: 1 | O22: =Осн.таблица!I32 -> 23.114727 | P22: =Осн.таблица!I31 -> 117.88527 | Q22: Валок наборной | T22: 220 | U22: 455 | V22: =IF(T21=0,VLOOKUP(U22,'Наст. эксц.'!$B$21:$C$30,2),VLOOKUP(U22,'Наст. эксц.'!$H$21:$I$30,2)) -> 455 | W22: =VLOOKUP(U22,'Наст. эксц.'!D21:E307,2) -> 95 | X22: 145 | Y22: ― | Z22: =Осн.таблица!I4 -> 216.75055 | AA22: =IF($T$21=0,570-(125+(AC22+U22)/2),0) -> 109.11473 | AB22: =Осн.таблица!I33 -> 7.5 | AC22: =Осн.таблица!I15 -> 216.77055 | AD22: 3
A23: Суммарные обжатия | F23: =SUM(F17:F22) -> 62 | G23: Пл/масса | I23: =(2*O6*(K6+M6-2*O6)-(4-3.1415)*(K10^2-(K10-O6)^2))/10^2 -> 59.33128 | J23: =0.785*I23 -> 46.575055 | K23: ГВ | L23: =SUM(L17:M22) -> 28 | N23: * где, а - среднее значение сторон профиля (А+В)/2 | AA23: Ось прокатки - | AB23: =Осн.таблица!C23 -> 1335 | AC23: ВВ | AD23: =F23-L23 -> 34
C24: СОГЛАСОВАНО
C25: Тех. Отдел | Y25: ______________________________
Y26: (фамилимя, подпись)
C27: ИСПОЛНИТЕЛЬ
C28: Технолог | Y28: ______________________________
Y29: (фамилимя, подпись)

Sheet 1,273 - Коэфициент
D1: Диаметр
D2: 40 | E2: 50 | F2: 60 | G2: 70 | H2: 80 | I2: 90 | J2: 100 | K2: 110 | L2: 120 | M2: 130 | N2: 140 | O2: 150 | P2: 160 | Q2: 170 | R2: 180 | S2: 190 | T2: 200 | U2: 210 | V2: 220
A3: 1.6 | B3: 4 | C3: =1.72*A$3/3.1415 -> 0.87601464 | D3: =(1.273-((1.72*A$3/3.1415)*(B3/$D$2)))*$D$2 -> 47.415941 | E3: =(1.273-((1.72*$A3/3.1415)*($B3/$E$2)))*$E$2 -> 60.145941 | F3: =(1.273-((1.72*$A3/3.1415)*($B3/$F$2)))*$F$2 -> 72.875941 | G3: =(1.273-((1.72*$A3/3.1415)*($B3/$G$2)))*$G$2 -> 85.605941 | H3: =(1.273-((1.72*$A3/3.1415)*($B3/$H$2)))*$H$2 -> 98.335941 | I3: =(1.273-((1.72*$A3/3.1415)*($B3/$I$2)))*$I$2 -> 111.06594 | J3: =(1.273-((1.72*$A3/3.1415)*($B3/$J$2)))*$J$2 -> 123.79594 | K3: =(1.273-((1.72*$A3/3.1415)*($B3/$K$2)))*$K$2 -> 136.52594 | L3: =(1.273-((1.72*$A3/3.1415)*($B3/$L$2)))*$L$2 -> 149.25594 | M3: =(1.273-((1.72*$A3/3.1415)*($B3/$M$2)))*$M$2 -> 161.98594 | N3: =(1.273-((1.72*$A3/3.1415)*($B3/$N$2)))*$N$2 -> 174.71594 | O3: =(1.273-((1.72*$A3/3.1415)*($B3/$O$2)))*$O$2 -> 187.44594 | P3: =(1.273-((1.72*$A3/3.1415)*($B3/$P$2)))*$P$2 -> 200.17594 | Q3: =(1.273-((1.72*$A3/3.1415)*($B3/$Q$2)))*$Q$2 -> 212.90594 | R3: =(1.273-((1.72*$A3/3.1415)*($B3/$R$2)))*$R$2 -> 225.63594 | S3: =(1.273-((1.72*$A3/3.1415)*($B3/$S$2)))*$S$2 -> 238.36594 | T3: =(1.273-((1.72*$A3/3.1415)*($B3/$T$2)))*$T$2 -> 251.09594 | U3: =(1.273-((1.72*$A3/3.1415)*($B3/$U$2)))*$U$2 -> 263.82594 | V3: =(1.273-((1.72*$A3/3.1415)*($B3/$V$2)))*$V$2 -> 276.55594
A4: 2 | B4: 5 | C4: =1.72*A$3/3.1415 -> 0.87601464 | D4: =(1.273-((1.72*A$4/3.1415)*(B4/$D$2)))*$D$2 -> 45.444908 | E4: =(1.273-((1.72*$A4/3.1415)*($B4/$E$2)))*$E$2 -> 58.174908 | F4: =(1.273-((1.72*$A4/3.1415)*($B4/$F$2)))*$F$2 -> 70.904908 | G4: =(1.273-((1.72*$A4/3.1415)*($B4/$G$2)))*$G$2 -> 83.634908 | H4: =(1.273-((1.72*$A4/3.1415)*($B4/$H$2)))*$H$2 -> 96.364908 | I4: =(1.273-((1.72*$A4/3.1415)*($B4/$I$2)))*$I$2 -> 109.09491 | J4: =(1.273-((1.72*$A4/3.1415)*($B4/$J$2)))*$J$2 -> 121.82491 | K4: =(1.273-((1.72*$A4/3.1415)*($B4/$K$2)))*$K$2 -> 134.55491 | L4: =(1.273-((1.72*$A4/3.1415)*($B4/$L$2)))*$L$2 -> 147.28491 | M4: =(1.273-((1.72*$A4/3.1415)*($B4/$M$2)))*$M$2 -> 160.01491 | N4: =(1.273-((1.72*$A4/3.1415)*($B4/$N$2)))*$N$2 -> 172.74491 | O4: =(1.273-((1.72*$A4/3.1415)*($B4/$O$2)))*$O$2 -> 185.47491 | P4: =(1.273-((1.72*$A4/3.1415)*($B4/$P$2)))*$P$2 -> 198.20491 | Q4: =(1.273-((1.72*$A4/3.1415)*($B4/$Q$2)))*$Q$2 -> 210.93491 | R4: =(1.273-((1.72*$A4/3.1415)*($B4/$R$2)))*$R$2 -> 223.66491 | S4: =(1.273-((1.72*$A4/3.1415)*($B4/$S$2)))*$S$2 -> 236.39491 | T4: =(1.273-((1.72*$A4/3.1415)*($B4/$T$2)))*$T$2 -> 249.12491 | U4: =(1.273-((1.72*$A4/3.1415)*($B4/$U$2)))*$U$2 -> 261.85491 | V4: =(1.273-((1.72*$A4/3.1415)*($B4/$V$2)))*$V$2 -> 274.58491
A5: 2.4 | B5: 6 | C5: =1.72*A$3/3.1415 -> 0.87601464 | D5: =(1.273-((1.72*A$5/3.1415)*(B5/$D$2)))*$D$2 -> 43.035868 | E5: =(1.273-((1.72*$A5/3.1415)*($B5/$E$2)))*$E$2 -> 55.765868 | F5: =(1.273-((1.72*$A5/3.1415)*($B5/$F$2)))*$F$2 -> 68.495868 | G5: =(1.273-((1.72*$A5/3.1415)*($B5/$G$2)))*$G$2 -> 81.225868 | H5: =(1.273-((1.72*$A5/3.1415)*($B5/$H$2)))*$H$2 -> 93.955868 | I5: =(1.273-((1.72*$A5/3.1415)*($B5/$I$2)))*$I$2 -> 106.68587 | J5: =(1.273-((1.72*$A5/3.1415)*($B5/$J$2)))*$J$2 -> 119.41587 | K5: =(1.273-((1.72*$A5/3.1415)*($B5/$K$2)))*$K$2 -> 132.14587 | L5: =(1.273-((1.72*$A5/3.1415)*($B5/$L$2)))*$L$2 -> 144.87587 | M5: =(1.273-((1.72*$A5/3.1415)*($B5/$M$2)))*$M$2 -> 157.60587 | N5: =(1.273-((1.72*$A5/3.1415)*($B5/$N$2)))*$N$2 -> 170.33587 | O5: =(1.273-((1.72*$A5/3.1415)*($B5/$O$2)))*$O$2 -> 183.06587 | P5: =(1.273-((1.72*$A5/3.1415)*($B5/$P$2)))*$P$2 -> 195.79587 | Q5: =(1.273-((1.72*$A5/3.1415)*($B5/$Q$2)))*$Q$2 -> 208.52587 | R5: =(1.273-((1.72*$A5/3.1415)*($B5/$R$2)))*$R$2 -> 221.25587 | S5: =(1.273-((1.72*$A5/3.1415)*($B5/$S$2)))*$S$2 -> 233.98587 | T5: =(1.273-((1.72*$A5/3.1415)*($B5/$T$2)))*$T$2 -> 246.71587 | U5: =(1.273-((1.72*$A5/3.1415)*($B5/$U$2)))*$U$2 -> 259.44587 | V5: =(1.273-((1.72*$A5/3.1415)*($B5/$V$2)))*$V$2 -> 272.17587
A6: 2 | B6: 7 | C6: =1.72*A$6/3.1415 -> 1.0950183 | D6: =(1.273-((1.72*A$6/3.1415)*(B6/$D$2)))*$D$2 -> 43.254872 | E6: =(1.273-((1.72*$A6/3.1415)*($B6/$E$2)))*$E$2 -> 55.984872 | F6: =(1.273-((1.72*$A6/3.1415)*($B6/$F$2)))*$F$2 -> 68.714872 | G6: =(1.273-((1.72*$A6/3.1415)*($B6/$G$2)))*$G$2 -> 81.444872 | H6: =(1.273-((1.72*$A6/3.1415)*($B6/$H$2)))*$H$2 -> 94.174872 | I6: =(1.273-((1.72*$A6/3.1415)*($B6/$I$2)))*$I$2 -> 106.90487 | J6: =(1.273-((1.72*$A6/3.1415)*($B6/$J$2)))*$J$2 -> 119.63487 | K6: =(1.273-((1.72*$A6/3.1415)*($B6/$K$2)))*$K$2 -> 132.36487 | L6: =(1.273-((1.72*$A6/3.1415)*($B6/$L$2)))*$L$2 -> 145.09487 | M6: =(1.273-((1.72*$A6/3.1415)*($B6/$M$2)))*$M$2 -> 157.82487 | N6: =(1.273-((1.72*$A6/3.1415)*($B6/$N$2)))*$N$2 -> 170.55487 | O6: =(1.273-((1.72*$A6/3.1415)*($B6/$O$2)))*$O$2 -> 183.28487 | P6: =(1.273-((1.72*$A6/3.1415)*($B6/$P$2)))*$P$2 -> 196.01487 | Q6: =(1.273-((1.72*$A6/3.1415)*($B6/$Q$2)))*$Q$2 -> 208.74487 | R6: =(1.273-((1.72*$A6/3.1415)*($B6/$R$2)))*$R$2 -> 221.47487 | S6: =(1.273-((1.72*$A6/3.1415)*($B6/$S$2)))*$S$2 -> 234.20487 | T6: =(1.273-((1.72*$A6/3.1415)*($B6/$T$2)))*$T$2 -> 246.93487 | U6: =(1.273-((1.72*$A6/3.1415)*($B6/$U$2)))*$U$2 -> 259.66487 | V6: =(1.273-((1.72*$A6/3.1415)*($B6/$V$2)))*$V$2 -> 272.39487
A7: 2.3 | B7: 8 | C7: =1.72*A$6/3.1415 -> 1.0950183 | D7: =(1.273-((1.72*A$7/3.1415)*(B7/$D$2)))*$D$2 -> 40.845832 | E7: =(1.273-((1.72*$A7/3.1415)*($B7/$E$2)))*$E$2 -> 53.575832 | F7: =(1.273-((1.72*$A7/3.1415)*($B7/$F$2)))*$F$2 -> 66.305832 | G7: =(1.273-((1.72*$A7/3.1415)*($B7/$G$2)))*$G$2 -> 79.035832 | H7: =(1.273-((1.72*$A7/3.1415)*($B7/$H$2)))*$H$2 -> 91.765832 | I7: =(1.273-((1.72*$A7/3.1415)*($B7/$I$2)))*$I$2 -> 104.49583 | J7: =(1.273-((1.72*$A7/3.1415)*($B7/$J$2)))*$J$2 -> 117.22583 | K7: =(1.273-((1.72*$A7/3.1415)*($B7/$K$2)))*$K$2 -> 129.95583 | L7: =(1.273-((1.72*$A7/3.1415)*($B7/$L$2)))*$L$2 -> 142.68583 | M7: =(1.273-((1.72*$A7/3.1415)*($B7/$M$2)))*$M$2 -> 155.41583 | N7: =(1.273-((1.72*$A7/3.1415)*($B7/$N$2)))*$N$2 -> 168.14583 | O7: =(1.273-((1.72*$A7/3.1415)*($B7/$O$2)))*$O$2 -> 180.87583 | P7: =(1.273-((1.72*$A7/3.1415)*($B7/$P$2)))*$P$2 -> 193.60583 | Q7: =(1.273-((1.72*$A7/3.1415)*($B7/$Q$2)))*$Q$2 -> 206.33583 | R7: =(1.273-((1.72*$A7/3.1415)*($B7/$R$2)))*$R$2 -> 219.06583 | S7: =(1.273-((1.72*$A7/3.1415)*($B7/$S$2)))*$S$2 -> 231.79583 | T7: =(1.273-((1.72*$A7/3.1415)*($B7/$T$2)))*$T$2 -> 244.52583 | U7: =(1.273-((1.72*$A7/3.1415)*($B7/$U$2)))*$U$2 -> 257.25583 | V7: =(1.273-((1.72*$A7/3.1415)*($B7/$V$2)))*$V$2 -> 269.98583
A8: 2.6 | B8: 9 | C8: =1.72*A$6/3.1415 -> 1.0950183 | D8: =(1.273-((1.72*A$8/3.1415)*(B8/$D$2)))*$D$2 -> 38.108286 | E8: =(1.273-((1.72*$A8/3.1415)*($B8/$E$2)))*$E$2 -> 50.838286 | F8: =(1.273-((1.72*$A8/3.1415)*($B8/$F$2)))*$F$2 -> 63.568286 | G8: =(1.273-((1.72*$A8/3.1415)*($B8/$G$2)))*$G$2 -> 76.298286 | H8: =(1.273-((1.72*$A8/3.1415)*($B8/$H$2)))*$H$2 -> 89.028286 | I8: =(1.273-((1.72*$A8/3.1415)*($B8/$I$2)))*$I$2 -> 101.75829 | J8: =(1.273-((1.72*$A8/3.1415)*($B8/$J$2)))*$J$2 -> 114.48829 | K8: =(1.273-((1.72*$A8/3.1415)*($B8/$K$2)))*$K$2 -> 127.21829 | L8: =(1.273-((1.72*$A8/3.1415)*($B8/$L$2)))*$L$2 -> 139.94829 | M8: =(1.273-((1.72*$A8/3.1415)*($B8/$M$2)))*$M$2 -> 152.67829 | N8: =(1.273-((1.72*$A8/3.1415)*($B8/$N$2)))*$N$2 -> 165.40829 | O8: =(1.273-((1.72*$A8/3.1415)*($B8/$O$2)))*$O$2 -> 178.13829 | P8: =(1.273-((1.72*$A8/3.1415)*($B8/$P$2)))*$P$2 -> 190.86829 | Q8: =(1.273-((1.72*$A8/3.1415)*($B8/$Q$2)))*$Q$2 -> 203.59829 | R8: =(1.273-((1.72*$A8/3.1415)*($B8/$R$2)))*$R$2 -> 216.32829 | S8: =(1.273-((1.72*$A8/3.1415)*($B8/$S$2)))*$S$2 -> 229.05829 | T8: =(1.273-((1.72*$A8/3.1415)*($B8/$T$2)))*$T$2 -> 241.78829 | U8: =(1.273-((1.72*$A8/3.1415)*($B8/$U$2)))*$U$2 -> 254.51829 | V8: =(1.273-((1.72*$A8/3.1415)*($B8/$V$2)))*$V$2 -> 267.24829
A9: 3 | B9: 10 | C9: =1.72*A$6/3.1415 -> 1.0950183 | D9: =(1.273-((1.72*A$9/3.1415)*(B9/$D$2)))*$D$2 -> 34.494725 | E9: =(1.273-((1.72*$A9/3.1415)*($B9/$E$2)))*$E$2 -> 47.224725 | F9: =(1.273-((1.72*$A9/3.1415)*($B9/$F$2)))*$F$2 -> 59.954725 | G9: =(1.273-((1.72*$A9/3.1415)*($B9/$G$2)))*$G$2 -> 72.684725 | H9: =(1.273-((1.72*$A9/3.1415)*($B9/$H$2)))*$H$2 -> 85.414725 | I9: =(1.273-((1.72*$A9/3.1415)*($B9/$I$2)))*$I$2 -> 98.144725 | J9: =(1.273-((1.72*$A9/3.1415)*($B9/$J$2)))*$J$2 -> 110.87473 | K9: =(1.273-((1.72*$A9/3.1415)*($B9/$K$2)))*$K$2 -> 123.60473 | L9: =(1.273-((1.72*$A9/3.1415)*($B9/$L$2)))*$L$2 -> 136.33473 | M9: =(1.273-((1.72*$A9/3.1415)*($B9/$M$2)))*$M$2 -> 149.06473 | N9: =(1.273-((1.72*$A9/3.1415)*($B9/$N$2)))*$N$2 -> 161.79473 | O9: =(1.273-((1.72*$A9/3.1415)*($B9/$O$2)))*$O$2 -> 174.52473 | P9: =(1.273-((1.72*$A9/3.1415)*($B9/$P$2)))*$P$2 -> 187.25473 | Q9: =(1.273-((1.72*$A9/3.1415)*($B9/$Q$2)))*$Q$2 -> 199.98473 | R9: =(1.273-((1.72*$A9/3.1415)*($B9/$R$2)))*$R$2 -> 212.71473 | S9: =(1.273-((1.72*$A9/3.1415)*($B9/$S$2)))*$S$2 -> 225.44473 | T9: =(1.273-((1.72*$A9/3.1415)*($B9/$T$2)))*$T$2 -> 238.17473 | U9: =(1.273-((1.72*$A9/3.1415)*($B9/$U$2)))*$U$2 -> 250.90473 | V9: =(1.273-((1.72*$A9/3.1415)*($B9/$V$2)))*$V$2 -> 263.63473
A10: 2.4 | B10: 11 | C10: =1.72*A$10/3.1415 -> 1.314022 | D10: =(1.273-((1.72*A$10/3.1415)*(B10/$D$2)))*$D$2 -> 36.465758 | E10: =(1.273-((1.72*$A10/3.1415)*($B10/$E$2)))*$E$2 -> 49.195758 | F10: =(1.273-((1.72*$A10/3.1415)*($B10/$F$2)))*$F$2 -> 61.925758 | G10: =(1.273-((1.72*$A10/3.1415)*($B10/$G$2)))*$G$2 -> 74.655758 | H10: =(1.273-((1.72*$A10/3.1415)*($B10/$H$2)))*$H$2 -> 87.385758 | I10: =(1.273-((1.72*$A10/3.1415)*($B10/$I$2)))*$I$2 -> 100.11576 | J10: =(1.273-((1.72*$A10/3.1415)*($B10/$J$2)))*$J$2 -> 112.84576 | K10: =(1.273-((1.72*$A10/3.1415)*($B10/$K$2)))*$K$2 -> 125.57576 | L10: =(1.273-((1.72*$A10/3.1415)*($B10/$L$2)))*$L$2 -> 138.30576 | M10: =(1.273-((1.72*$A10/3.1415)*($B10/$M$2)))*$M$2 -> 151.03576 | N10: =(1.273-((1.72*$A10/3.1415)*($B10/$N$2)))*$N$2 -> 163.76576 | O10: =(1.273-((1.72*$A10/3.1415)*($B10/$O$2)))*$O$2 -> 176.49576 | P10: =(1.273-((1.72*$A10/3.1415)*($B10/$P$2)))*$P$2 -> 189.22576 | Q10: =(1.273-((1.72*$A10/3.1415)*($B10/$Q$2)))*$Q$2 -> 201.95576 | R10: =(1.273-((1.72*$A10/3.1415)*($B10/$R$2)))*$R$2 -> 214.68576 | S10: =(1.273-((1.72*$A10/3.1415)*($B10/$S$2)))*$S$2 -> 227.41576 | T10: =(1.273-((1.72*$A10/3.1415)*($B10/$T$2)))*$T$2 -> 240.14576 | U10: =(1.273-((1.72*$A10/3.1415)*($B10/$U$2)))*$U$2 -> 252.87576 | V10: =(1.273-((1.72*$A10/3.1415)*($B10/$V$2)))*$V$2 -> 265.60576
A11: 2.8 | B11: 12 | C11: =1.72*A$10/3.1415 -> 1.314022 | D11: =(1.273-((1.72*A$11/3.1415)*(B11/$D$2)))*$D$2 -> 32.523693 | E11: =(1.273-((1.72*$A11/3.1415)*($B11/$E$2)))*$E$2 -> 45.253693 | F11: =(1.273-((1.72*$A11/3.1415)*($B11/$F$2)))*$F$2 -> 57.983693 | G11: =(1.273-((1.72*$A11/3.1415)*($B11/$G$2)))*$G$2 -> 70.713693 | H11: =(1.273-((1.72*$A11/3.1415)*($B11/$H$2)))*$H$2 -> 83.443693 | I11: =(1.273-((1.72*$A11/3.1415)*($B11/$I$2)))*$I$2 -> 96.173693 | J11: =(1.273-((1.72*$A11/3.1415)*($B11/$J$2)))*$J$2 -> 108.90369 | K11: =(1.273-((1.72*$A11/3.1415)*($B11/$K$2)))*$K$2 -> 121.63369 | L11: =(1.273-((1.72*$A11/3.1415)*($B11/$L$2)))*$L$2 -> 134.36369 | M11: =(1.273-((1.72*$A11/3.1415)*($B11/$M$2)))*$M$2 -> 147.09369 | N11: =(1.273-((1.72*$A11/3.1415)*($B11/$N$2)))*$N$2 -> 159.82369 | O11: =(1.273-((1.72*$A11/3.1415)*($B11/$O$2)))*$O$2 -> 172.55369 | P11: =(1.273-((1.72*$A11/3.1415)*($B11/$P$2)))*$P$2 -> 185.28369 | Q11: =(1.273-((1.72*$A11/3.1415)*($B11/$Q$2)))*$Q$2 -> 198.01369 | R11: =(1.273-((1.72*$A11/3.1415)*($B11/$R$2)))*$R$2 -> 210.74369 | S11: =(1.273-((1.72*$A11/3.1415)*($B11/$S$2)))*$S$2 -> 223.47369 | T11: =(1.273-((1.72*$A11/3.1415)*($B11/$T$2)))*$T$2 -> 236.20369 | U11: =(1.273-((1.72*$A11/3.1415)*($B11/$U$2)))*$U$2 -> 248.93369 | V11: =(1.273-((1.72*$A11/3.1415)*($B11/$V$2)))*$V$2 -> 261.66369
A12: 3.2 | B12: 13 | C12: =1.72*A$10/3.1415 -> 1.314022 | D12: =(1.273-((1.72*A$12/3.1415)*(B12/$D$2)))*$D$2 -> 28.143619 | E12: =(1.273-((1.72*$A12/3.1415)*($B12/$E$2)))*$E$2 -> 40.873619 | F12: =(1.273-((1.72*$A12/3.1415)*($B12/$F$2)))*$F$2 -> 53.603619 | G12: =(1.273-((1.72*$A12/3.1415)*($B12/$G$2)))*$G$2 -> 66.333619 | H12: =(1.273-((1.72*$A12/3.1415)*($B12/$H$2)))*$H$2 -> 79.063619 | I12: =(1.273-((1.72*$A12/3.1415)*($B12/$I$2)))*$I$2 -> 91.793619 | J12: =(1.273-((1.72*$A12/3.1415)*($B12/$J$2)))*$J$2 -> 104.52362 | K12: =(1.273-((1.72*$A12/3.1415)*($B12/$K$2)))*$K$2 -> 117.25362 | L12: =(1.273-((1.72*$A12/3.1415)*($B12/$L$2)))*$L$2 -> 129.98362 | M12: =(1.273-((1.72*$A12/3.1415)*($B12/$M$2)))*$M$2 -> 142.71362 | N12: =(1.273-((1.72*$A12/3.1415)*($B12/$N$2)))*$N$2 -> 155.44362 | O12: =(1.273-((1.72*$A12/3.1415)*($B12/$O$2)))*$O$2 -> 168.17362 | P12: =(1.273-((1.72*$A12/3.1415)*($B12/$P$2)))*$P$2 -> 180.90362 | Q12: =(1.273-((1.72*$A12/3.1415)*($B12/$Q$2)))*$Q$2 -> 193.63362 | R12: =(1.273-((1.72*$A12/3.1415)*($B12/$R$2)))*$R$2 -> 206.36362 | S12: =(1.273-((1.72*$A12/3.1415)*($B12/$S$2)))*$S$2 -> 219.09362 | T12: =(1.273-((1.72*$A12/3.1415)*($B12/$T$2)))*$T$2 -> 231.82362 | U12: =(1.273-((1.72*$A12/3.1415)*($B12/$U$2)))*$U$2 -> 244.55362 | V12: =(1.273-((1.72*$A12/3.1415)*($B12/$V$2)))*$V$2 -> 257.28362
A13: 3.6 | B13: 14 | C13: =1.72*A$10/3.1415 -> 1.314022 | D13: =(1.273-((1.72*A$13/3.1415)*(B13/$D$2)))*$D$2 -> 23.325539 | E13: =(1.273-((1.72*$A13/3.1415)*($B13/$E$2)))*$E$2 -> 36.055539 | F13: =(1.273-((1.72*$A13/3.1415)*($B13/$F$2)))*$F$2 -> 48.785539 | G13: =(1.273-((1.72*$A13/3.1415)*($B13/$G$2)))*$G$2 -> 61.515539 | H13: =(1.273-((1.72*$A13/3.1415)*($B13/$H$2)))*$H$2 -> 74.245539 | I13: =(1.273-((1.72*$A13/3.1415)*($B13/$I$2)))*$I$2 -> 86.975539 | J13: =(1.273-((1.72*$A13/3.1415)*($B13/$J$2)))*$J$2 -> 99.705539 | K13: =(1.273-((1.72*$A13/3.1415)*($B13/$K$2)))*$K$2 -> 112.43554 | L13: =(1.273-((1.72*$A13/3.1415)*($B13/$L$2)))*$L$2 -> 125.16554 | M13: =(1.273-((1.72*$A13/3.1415)*($B13/$M$2)))*$M$2 -> 137.89554 | N13: =(1.273-((1.72*$A13/3.1415)*($B13/$N$2)))*$N$2 -> 150.62554 | O13: =(1.273-((1.72*$A13/3.1415)*($B13/$O$2)))*$O$2 -> 163.35554 | P13: =(1.273-((1.72*$A13/3.1415)*($B13/$P$2)))*$P$2 -> 176.08554 | Q13: =(1.273-((1.72*$A13/3.1415)*($B13/$Q$2)))*$Q$2 -> 188.81554 | R13: =(1.273-((1.72*$A13/3.1415)*($B13/$R$2)))*$R$2 -> 201.54554 | S13: =(1.273-((1.72*$A13/3.1415)*($B13/$S$2)))*$S$2 -> 214.27554 | T13: =(1.273-((1.72*$A13/3.1415)*($B13/$T$2)))*$T$2 -> 227.00554 | U13: =(1.273-((1.72*$A13/3.1415)*($B13/$U$2)))*$U$2 -> 239.73554 | V13: =(1.273-((1.72*$A13/3.1415)*($B13/$V$2)))*$V$2 -> 252.46554
D14: Коффициент
D15: 40 | E15: 50 | F15: 60 | G15: 70 | H15: 80 | I15: 90 | J15: 100 | K15: 110 | L15: 120 | M15: 130 | N15: 140 | O15: 150 | P15: 160 | Q15: 170 | R15: 180 | S15: 190 | T15: 200 | U15: 210 | V15: 220
A16: 1.6 | B16: 4 | C16: =1.72*A$3/3.1415 -> 0.87601464 | D16: =1.273-1.095*($B16/D$15) -> 1.1635 | E16: =1.273-1.095*($B16/E$15) -> 1.1854 | F16: =1.273-1.095*$B16/F$15 -> 1.2 | G16: =1.273-1.095*$B16/G$15 -> 1.2104286 | H16: =1.273-1.095*$B16/H$15 -> 1.21825 | I16: =1.273-1.095*$B16/I$15 -> 1.2243333 | J16: =1.273-1.095*$B16/J$15 -> 1.2292 | K16: =1.273-1.095*$B16/K$15 -> 1.2331818 | L16: =1.273-1.095*$B16/L$15 -> 1.2365 | M16: =1.273-1.095*$B16/M$15 -> 1.2393077 | ... V16: =1.273-1.095*$B16/V$15 -> 1.2530909
A17: 2 | B17: 5 | C17: =1.72*A$3/3.1415 -> 0.87601464 | D17: =1.273-1.095*$B17/D$15 -> 1.136125 | E17: =1.273-1.095*$B17/E$15 -> 1.1635 | F17: =1.273-1.095*$B17/F$15 -> 1.18175 | G17: =1.273-1.095*$B17/G$15 -> 1.1947857 | H17: =1.273-1.095*$B17/H$15 -> 1.2045625 | I17: =1.273-1.095*$B17/I$15 -> 1.2121667 | J17: =1.273-1.095*$B17/J$15 -> 1.21825 | K17: =1.273-1.095*$B17/K$15 -> 1.2232273 | ... V17: =1.273-1.095*$B17/V$15 -> 1.2481136
A18: 2.4 | B18: 6 | C18: =1.72*A$3/3.1415 -> 0.87601464 | D18: =1.273-1.095*$B18/D$15 -> 1.10875 | E18: =1.273-1.095*$B18/E$15 -> 1.1416 | F18: =1.273-1.095*$B18/F$15 -> 1.1635 | G18: =1.273-1.095*$B18/G$15 -> 1.1791429 | H18: =1.273-1.095*$B18/H$15 -> 1.190875 | I18: =1.273-1.095*$B18/I$15 -> 1.2 | J18: =1.273-1.095*$B18/J$15 -> 1.2073 | K18: =1.273-1.095*$B18/K$15 -> 1.2132727 | ... V18: =1.273-1.095*$B18/V$15 -> 1.2431364
A19: 2 | B19: 7 | C19: =1.72*A$6/3.1415 -> 1.0950183 | D19: =1.273-1.095*$B19/D$15 -> 1.081375 | E19: =1.273-1.095*$B19/E$15 -> 1.1197 | F19: =1.273-1.095*$B19/F$15 -> 1.14525 | G19: =1.273-1.095*$B19/G$15 -> 1.1635 | H19: =1.273-1.095*$B19/H$15 -> 1.1771875 | I19: =1.273-1.095*$B19/I$15 -> 1.1878333 | J19: =1.273-1.095*$B19/J$15 -> 1.19635 | K19: =1.273-1.095*$B19/K$15 -> 1.2033182 | ... V19: =1.273-1.095*$B19/V$15 -> 1.2381591
A20: 2.3 | B20: 8 | C20: =1.72*A$6/3.1415 -> 1.0950183 | D20: =1.273-1.095*$B20/D$15 -> 1.054 | E20: =1.273-1.095*$B20/E$15 -> 1.0978 | F20: =1.273-1.095*$B20/F$15 -> 1.127 | G20: =1.273-1.095*$B20/G$15 -> 1.1478571 | H20: =1.273-1.095*$B20/H$15 -> 1.1635 | I20: =1.273-1.095*$B20/I$15 -> 1.1756667 | J20: =1.273-1.095*$B20/J$15 -> 1.1854 | K20: =1.273-1.095*$B20/K$15 -> 1.1933636 | ... V20: =1.273-1.095*$B20/V$15 -> 1.2331818
A21: 2.6 | B21: 9 | C21: =1.72*A$6/3.1415 -> 1.0950183 | D21: =1.273-1.095*$B21/D$15 -> 1.026625 | E21: =1.273-1.095*$B21/E$15 -> 1.0759 | F21: =1.273-1.095*$B21/F$15 -> 1.10875 | G21: =1.273-1.095*$B21/G$15 -> 1.1322143 | H21: =1.273-1.095*$B21/H$15 -> 1.1498125 | I21: =1.273-1.095*$B21/I$15 -> 1.1635 | J21: =1.273-1.095*$B21/J$15 -> 1.17445 | K21: =1.273-1.095*$B21/K$15 -> 1.1834091 | ... V21: =1.273-1.095*$B21/V$15 -> 1.2282045
A22: 3 | B22: 10 | C22: =1.72*A$6/3.1415 -> 1.0950183 | D22: =1.273-1.095*$B22/D$15 -> 0.99925 | E22: =1.273-1.095*$B22/E$15 -> 1.054 | F22: =1.273-1.095*$B22/F$15 -> 1.0905 | G22: =1.273-1.095*$B22/G$15 -> 1.1165714 | H22: =1.273-1.095*$B22/H$15 -> 1.136125 | I22: =1.273-1.095*$B22/I$15 -> 1.1513333 | J22: =1.273-1.095*$B22/J$15 -> 1.1635 | K22: =1.273-1.095*$B22/K$15 -> 1.1734545 | ... V22: =1.273-1.095*$B22/V$15 -> 1.2232273
A23: 2.4 | B23: 11 | C23: =1.72*A$10/3.1415 -> 1.314022 | D23: =1.273-1.095*$B23/D$15 -> 0.971875 | E23: =1.273-1.095*$B23/E$15 -> 1.0321 | F23: =1.273-1.095*$B23/F$15 -> 1.07225 | G23: =1.273-1.095*$B23/G$15 -> 1.1009286 | H23: =1.273-1.095*$B23/H$15 -> 1.1224375 | I23: =1.273-1.095*$B23/I$15 -> 1.1391667 | J23: =1.273-1.095*$B23/J$15 -> 1.15255 | K23: =1.273-1.095*$B23/K$15 -> 1.1635 | ... V23: =1.273-1.095*$B23/V$15 -> 1.21825
A24: 2.8 | B24: 12 | C24: =1.72*A$10/3.1415 -> 1.314022 | D24: =1.273-1.095*$B24/D$15 -> 0.9445 | E24: =1.273-1.095*$B24/E$15 -> 1.0102 | F24: =1.273-1.095*$B24/F$15 -> 1.054 | G24: =1.273-1.095*$B24/G$15 -> 1.0852857 | H24: =1.273-1.095*$B24/H$15 -> 1.10875 | I24: =1.273-1.095*$B24/I$15 -> 1.127 | J24: =1.273-1.095*$B24/J$15 -> 1.1416 | K24: =1.273-1.095*$B24/K$15 -> 1.1535455 | ... V24: =1.273-1.095*$B24/V$15 -> 1.2132727
A25: 3.2 | B25: 13 | C25: =1.72*A$10/3.1415 -> 1.314022 | D25: =1.273-1.095*$B25/D$15 -> 0.917125 | E25: =1.273-1.095*$B25/E$15 -> 0.9883 | F25: =1.273-1.095*$B25/F$15 -> 1.03575 | G25: =1.273-1.095*$B25/G$15 -> 1.0696429 | H25: =1.273-1.095*$B25/H$15 -> 1.0950625 | I25: =1.273-1.095*$B25/I$15 -> 1.1148333 | J25: =1.273-1.095*$B25/J$15 -> 1.13065 | K25: =1.273-1.095*$B25/K$15 -> 1.1435909 | ... V25: =1.273-1.095*$B25/V$15 -> 1.2082955
A26: 3.6 | B26: 14 | C26: =1.72*A$10/3.1415 -> 1.314022 | D26: =1.273-1.095*$B26/D$15 -> 0.88975 | E26: =1.273-1.095*$B26/E$15 -> 0.9664 | F26: =1.273-1.095*$B26/F$15 -> 1.0175 | G26: =1.273-1.095*$B26/G$15 -> 1.054 | H26: =1.273-1.095*$B26/H$15 -> 1.081375 | I26: =1.273-1.095*$B26/I$15 -> 1.1026667 | J26: =1.273-1.095*$B26/J$15 -> 1.1197 | K26: =1.273-1.095*$B26/K$15 -> 1.1336364 | ... V26: =1.273-1.095*$B26/V$15 -> 1.2033182

Sheet Коэф
C1: =C5*I1 -> 12.8 | D1: =D5*I1 -> 19.2 | G1: ='Карта настройки'!X6 -> 245.77055 | H1: =PI()*G1 -> 772.11094 | I1: ='Карта настройки'!O6 -> 8 | J1: =H1/H2 -> 1.1988807
C2: =C10*I1 -> 16 | D2: =D10*I1 -> 24 | G2: =('Карта настройки'!K6+'Карта настройки'!M6)/2 -> 205 | H2: =G2*PI() -> 644.02649
C3: =C15*I1 -> 19.2 | D3: =D15*I1 -> 28.8 | G3: =((4*G2)-1.72*D10*'Карта настройки'!O6)/(3.1415*G2) -> 1.2091785 | H3: =(((4*G2)-1.72*C10*'Карта настройки'!O6)/(3.1415*G2))+I19 -> 1.2551209
B4: Толщина стенки | C4: мин | D4: макс | F4: мин | G4: мах
B5: 6 | C5: 1.6 | D5: 2.4 | F5: =IF('Карта настройки'!$O$6<=Коэф!$B$5,C9,IF('Карта настройки'!$O$6<=Коэф!$B$10,C14,C19)) -> 1.2459024 | G5: =IF('Карта настройки'!$O$6<=Коэф!$B$5,D9,IF('Карта настройки'!$O$6<=Коэф!$B$10,D14,D19)) -> 1.2198508
C6: =(2.35-0.007*(ATAN(0.5*(1/($I$1*(1/C1-1/Осн.таблица!$C$9))))*180/3.1415))*C1/1.72 -> 15.322656 | D6: =(2.35-0.007*(ATAN(0.5*(1/($I$1*(1/D1-1/Осн.таблица!$C$9))))*180/3.1415))*D1/1.72 -> 21.966237 | F6: =F5*L6/100 -> 1.2459024 | G6: Периметр проф т | I6: =Осн.таблица!I26 -> 762.15115 | J6: =Осн.таблица!I25 -> 9.9597894 | K6: =I6+J6 -> 772.11094 | L6: =100-K22 -> 100
C7: =(3*$I$1)*(SQRT(((1/(C5*$I$1))-(1/($G$1/2)))*$I$1)) -> 17.95833 | D7: =(3*$I$1)*(SQRT(((1/(D5*$I$1))-(1/($G$1/2)))*$I$1)) -> 14.230306
C8: =((SQRT((1/C6-1/Осн.таблица!$C$9)*$I$1)*$I$1*3)+(2*($G$2+$G$2)-C6*1.72)) -> 809.93686 | D8: =((SQRT((1/D6-1/Осн.таблица!$C$9)*$I$1)*$I$1*3)+(2*($G$2+$G$2)-D6*1.72)) -> 795.42675 | I8: =I6/H2 -> 1.1834158
C9: =C8/H2 -> 1.2576142 | D9: =D8/H2 -> 1.2350839
B10: 10 | C10: 2 | D10: 3 | F10: =F5+F6 -> 2.4918049 | J10: =J6/(3.1415*G2) -> 0.015465331
C11: =(2.35-0.007*(ATAN(0.5*(1/($I$1*(1/C2-1/Осн.таблица!$C$9))))*180/3.1415))*C2/1.72 -> 18.686856 | D11: =(2.35-0.007*(ATAN(0.5*(1/($I$1*(1/D2-1/Осн.таблица!$C$9))))*180/3.1415))*D2/1.72 -> 26.788365 | F11: =F5+J10 -> 1.2613678 | I11: =4*G2-3.44*'Карта настройки'!O6 -> 792.48
C12: =(3*$I$1)*(SQRT(((1/(C10*$I$1))-(1/($G$1/2)))*$I$1)) -> 15.827243 | D12: =(3*$I$1)*(SQRT(((1/(D10*$I$1))-(1/($G$1/2)))*$I$1)) -> 12.429868
C13: =((SQRT((1/C11-1/Осн.таблица!$C$9)*$I$1)*$I$1*3)+(2*($G$2+$G$2)-C11*1.72)) -> 802.39419 | D13: =((SQRT((1/D11-1/Осн.таблица!$C$9)*$I$1)*$I$1*3)+(2*($G$2+$G$2)-D11*1.72)) -> 785.61621
C14: =C13/H2 -> 1.2459024 | D14: =D13/H2 -> 1.2198508
B15: 10 | C15: 2.4 | D15: 3.6 | I15: =(4*G2-1.72*(C10*I1))/(3.1415*G2)+I19 -> 1.2551209
C16: =(2.35-0.007*(ATAN(0.5*(1/($I$1*(1/C3-1/Осн.таблица!$C$9))))*180/3.1415))*C3/1.72 -> 21.966237 | D16: =(2.35-0.007*(ATAN(0.5*(1/($I$1*(1/D3-1/Осн.таблица!$C$9))))*180/3.1415))*D3/1.72 -> 31.543722 | G16: =1.273-1.095*('Карта настройки'!O6/Коэф!G2) -> 1.2302683
C17: =(3*$I$1)*(SQRT(((1/(C15*$I$1))-(1/($G$1/2)))*$I$1)) -> 14.230306 | D17: =(3*$I$1)*(SQRT(((1/(D15*$I$1))-(1/($G$1/2)))*$I$1)) -> 11.068045
C18: =((SQRT((1/C16-1/Осн.таблица!$C$9)*$I$1)*$I$1*3)+(2*($G$2+$G$2)-C16*1.72)) -> 795.42675 | D18: =((SQRT((1/D16-1/Осн.таблица!$C$9)*$I$1)*$I$1*3)+(2*($G$2+$G$2)-D16*1.72)) -> 776.2698
C19: =C18/H2 -> 1.2350839 | D19: =D18/H2 -> 1.2053383 | I19: =((3*I1)*(SQRT(((1/(C10*I1))-(1/(G1/2)))*I1))-I22)/(3.1415*G2) -> 0.024576177 | K19: =I6*100/I11 -> 96.17292
K22: =K1*100/J1 -> 0
E24: =(3*I1)*(SQRT(((1/(C10*I1))-(1/(G1/2)))*I1)) -> 15.827243 | G24: =(Осн.таблица!I26+Коэф!E24)/Коэф!H2 -> 1.2079913
E25: =(3*I1)*(SQRT(((1/(D10*I1))-(1/(G1/2)))*I1)) -> 12.429868 | G25: =(Осн.таблица!I26+Коэф!E25)/Коэф!H2 -> 1.2027161
F37: Толщина стенки | G37: мин | H37: макс
F38: <= 6 | G38: 1.6 | H38: 2.4
F39: c 6 до 10 включительно | G39: 2 | H39: 3
F40: больше > 10 | G40: 2.4 | H40: 3.6

Sheet Осн.таблица
A1: Маршрут проката профильной трубы | E1: ='Карта настройки'!N18 -> -6 | G1: ='Карта настройки'!N20 -> -6 | I1: ='Карта настройки'!N22 -> 0 | J1: =NOW() -> 46288.744
A2: ='Карта настройки'!K6 -> 250 | B2: АхВ | C2: Дз | D2: Кл.1 | E2: Кл.2 | F2: Кл.3 | G2: Кл.4 | H2: Кл.5 | I2: Кл.6 | J2: дД
A3: =C3/A7 -> 1.1988807 | B3: ΔДв | C3: =IF('Карта настройки'!X8=0,((SQRT((1/C7-1/C9)*A19)*A19*3)+(2*(A5+A6)-C7*1.72))/3.1415,'Карта настройки'!X8) -> 245.77055 | D3: ='Карта настройки'!L17 -> 5 | E3: =IF(D5-D3-(E8-D8)>=C3,C3-(D5-D3-(E8-D8)),E8-D8+E1) -> 13 | F3: ='Карта настройки'!L19 -> 2 | G3: =G8-F8+G1 -> 6 | H3: ='Карта настройки'!L21 -> 1 | I3: =I8-H8+I1 -> 2 | J3: =C3-I5 -> 29
B4: Нщ | C4: =C3*PI() -> 772.11094 | D4: =D5-D7 -> 164.37734 | E4: =E5-E7 -> 193.45597 | F4: =F5-F7 -> 208.9865 | G4: =G5-G7 -> 213.09646 | H4: =H5-H7 -> 215.91282 | I4: =I5-I7 -> 216.75055
A5: ='Карта настройки'!K6 -> 250 | B5: Аширина | D5: =IF(D3<=0,C3,C3-D3) -> 240.77055 | E5: =IF(E3<=0,C3,D5-E3) -> 227.77055 | F5: =IF(E3<=0,C3-F3,E5-F3) -> 225.77055 | G5: =F5-G3 -> 219.77055 | H5: =G5-H3 -> 218.77055 | I5: =H5-I3 -> 216.77055 | J5: =C3-J3 -> 216.77055
A6: ='Карта настройки'!M6 -> 160 | B6: Рг | C6: =IF('Карта настройки'!X8=0,'Карта настройки'!K10,'Карта настройки'!K12) -> 31 | D6: ='Карта настройки'!J17 -> 300 | E6: ='Карта настройки'!J18 -> 600 | F6: ='Карта настройки'!J19 -> 1200 | G6: ='Карта настройки'!J20 -> 3000 | H6: ='Карта настройки'!J21 -> 7000 | I6: 1000000
A7: =(A5+A6)/2 -> 205 | B7: 2Нг | C7: =IF('Карта настройки'!X8=0,(2.35-0.007*(ATAN(0.5*(1/(A19*(1/C6-1/C9))))*180/3.1415))*C6/1.72,'Карта настройки'!K12) -> 33.709888 | D7: =D6-SQRT(D6^2-(($D$10^2)/4)) -> 76.393202 | E7: =E6-SQRT(E6^2-($E$10^2/4)) -> 34.314575 | F7: =F6-SQRT(F6^2-($F$10^2/4)) -> 16.784043 | G7: =G6-SQRT(G6^2-($G$10^2/4)) -> 6.6740906 | H7: =H6-SQRT(H6^2-($H$10^2/4)) -> 2.8577262 | I7: =I6-SQRT(I6^2-($I$10^2/4)) -> 0.02
B8: Дг.мин | C8: =I21 -> 33.709888 | D8: ='Карта настройки'!I17 -> 529 | E8: ='Карта настройки'!I18 -> 548 | F8: ='Карта настройки'!I19 -> 565 | G8: ='Карта настройки'!I20 -> 577 | H8: ='Карта настройки'!I21 -> 587 | I8: ='Карта настройки'!I22 -> 589
A9: ='Карта настройки'!T18 -> 220 | B9: Дг.макс | C9: =(A5+A6)/3.1415 -> 130.5109 | D9: =D8+D7*2 -> 681.7864 | E9: =E8+E7*2 -> 616.62915 | F9: =F8+F7*2 -> 598.56809 | G9: =G8+G7*2 -> 590.34818 | H9: =H8+H7*2 -> 592.71545 | I9: =I8+I7*2 -> 589.04 | J9: =ATAN(0.5*(1/(H21*(1/J8-1/J11))))*(180/3.1415) -> #DIV/0!
A10: ='Карта настройки'!T20 -> 220 | B10: Вг.вал | C10: =(C3-A19)*3.14159 -> 746.97757 | D10: ='Карта настройки'!G17 -> 400 | E10: ='Карта настройки'!G18 -> 400 | F10: ='Карта настройки'!G19 -> 400 | G10: ='Карта настройки'!G20 -> 400 | H10: ='Карта настройки'!G21 -> 400 | I10: ='Карта настройки'!G22 -> 400
A11: ='Карта настройки'!T22 -> 220 | B11: Пос-ная | D11: =$C$23-(774+20+250+D12/2) -> 141 | E11: =$C$23-(774+20+250+E12/2) -> 141 | F11: =$C$23-(774+20+250+F12/2) -> 141 | G11: =$C$23-(774+20+250+G12/2) -> 141 | H11: =$C$23-(774+20+250+H12/2) -> 141 | I11: =$C$23-(774+20+250+I12/2) -> 141
A12: Шир.В.валка | B12: Кас+Рама | D12: =A9+80 -> 300 | E12: =A9+80 -> 300 | F12: =A10+80 -> 300 | G12: =A10+80 -> 300 | H12: =A11+80 -> 300 | I12: =A11+80 -> 300
A13: ='Карта настройки'!X17 -> 105 | B13: Моа | C13: =C6/A19 -> 3.875 | D13: =D5+D8 -> 769.77055 | E13: =E5+E8 -> 775.77055 | F13: =F5+F8 -> 790.77055 | G13: =G5+G8 -> 796.77055 | H13: =H5+H8 -> 805.77055 | I13: =I5+I8 -> 805.77055
A14: ='Карта настройки'!X18 -> 115 | B14: ΔДа | C14: =C7/A19 -> 4.213736 | D14: ='Карта настройки'!AD17 -> -5 | E14: ='Карта настройки'!AD18 -> 7 | F14: ='Карта настройки'!AD19 -> 9 | G14: ='Карта настройки'!AD20 -> 8 | H14: ='Карта настройки'!AD21 -> 7 | I14: ='Карта настройки'!AD22 -> 3 | J14: =C3-I15 -> 29
A15: ='Карта настройки'!X19 -> 125 | B15: Ввысота | C15: =C8/A19 -> 4.213736 | D15: =IF(D3<=0,C3,C3-(D14)) -> 250.77055 | E15: =IF(E3<=0,C3,D15-E14) -> 243.77055 | F15: =IF(F3<=0,$C$3,IF(E3<=0,(C3-F5)+E15,E15-F14)) -> 234.77055 | G15: =F15-G14 -> 226.77055 | H15: =G15-H14 -> 219.77055 | I15: =H15-I14 -> 216.77055 | J15: =I15 -> 216.77055
A16: ='Карта настройки'!X20 -> 125 | B16: Рв | D16: ='Карта настройки'!Y17 -> 300 | E16: ='Карта настройки'!Y18 -> 600 | F16: ='Карта настройки'!Y19 -> 600 | G16: ='Карта настройки'!Y20 -> 1500 | H16: ='Карта настройки'!Y21 -> 1500 | I16: 1000000
A17: ='Карта настройки'!X21 -> 135 | B17: 2Нв | C17: ='Карта настройки'!X10 -> 5 | D17: =(D16-SQRT(D16^2-(A13^2)/4))*2 -> 9.25894 | E17: =(E16-SQRT(E16^2-(A14^2)/4))*2 -> 5.5231271 | F17: =(F16-SQRT(F16^2-(A15^2)/4))*2 -> 6.5281738 | G17: =(G16-SQRT(G16^2-(A16^2)/4))*2 -> 2.6052979 | H17: =(H16-SQRT(H16^2-(A17^2)/4))*2 -> 3.0390393 | I17: =(I16-SQRT(I16^2-(A18^2)/4))*2 -> 0.00525625
A18: ='Карта настройки'!X22 -> 145 | B18: Дв.мин | C18: =POWER((C3-A19)/(2*C7-A19),1/C17) -> 1.3196094 | D18: ='Карта настройки'!U17 -> 410 | E18: ='Карта настройки'!U18 -> 410 | F18: ='Карта настройки'!U19 -> 410 | G18: ='Карта настройки'!U20 -> 410 | H18: ='Карта настройки'!U21 -> 410 | I18: ='Карта настройки'!U22 -> 455
A19: ='Карта настройки'!O6 -> 8 | B19: Дв.макс | C19: =C3/2 -> 122.88527 | D19: =D17*2+D18 -> 428.51788 | E19: =E18+E17*2 -> 421.04625 | F19: =F18+F17*2 -> 423.05635 | G19: =G18+G17*2 -> 415.2106 | H19: =H18+H17*2 -> 416.07808 | I19: =I18+I17*2 -> 455.01051
A20: 200 | B20: Мов | C20: =(C3-A19)/2 -> 118.88527 | D20: =D18+D15 -> 660.77055 | E20: =E18+E15 -> 653.77055 | F20: =F18+F15 -> 644.77055 | G20: =G18+G15 -> 636.77055 | H20: =H18+H15 -> 629.77055 | I20: =I18+I15 -> 671.77055
A21: Дл. Шпин | B21: Rн | D21: =IF(D3<=0,C19,C19-D3/2) -> 120.38527 | E21: =($C$20/$C$18)+($A$19/2) -> 94.091258 | F21: =IF(F3<=0,C19,IF(E3<=0,C19-F3/2,(E21-$A$19/2)/$C$18+$A$19/2)) -> 72.271154 | G21: =((F21-$A$19/2)/$C$18)+$A$19/2 -> 55.735879 | H21: =(G21-A19/2)/C18+A19/2 -> 43.205449 | I21: =(H21-A19/2)/C18+A19/2 -> 33.709888
A22: 1650 | B22: Меж.ос.раст | C22: 1250 | D22: =D13 -> 769.77055 | E22: =E8+E5 -> 775.77055 | F22: =F8+F5 -> 790.77055 | G22: =G8+G5 -> 796.77055 | H22: =H8+H5 -> 805.77055 | I22: =I8+I5 -> 805.77055
A23: ШестКлеть | B23: Угол в | C23: =C22+5+(A6/2) -> 1335 | E23: =DEGREES(ASIN(((($C$23+E22/2)-(1235+$A$24))/$A$22))) -> 4.7936172 | F23: =DEGREES(ASIN(((($C$23+F22/2)-(1235+$A$24))/$A$22))) -> 5.0550176 | G23: =DEGREES(ASIN(((($C$23+G22/2)-(1235+$A$24))/$A$22))) -> 5.159607 | H23: =DEGREES(ASIN(((($C$23+H22/2)-(1235+$A$24))/$A$22))) -> 5.3165236 | I23: =DEGREES(ASIN(((($C$23+I22/2)-(1235+$A$24))/$A$22))) -> 5.3165236
A24: 350 | B24: Угол н | E24: =DEGREES(ASIN((1235-($C$23-E22/2))/$A$22)) -> 10.048162 | F24: =DEGREES(ASIN((1235-($C$23-F22/2))/$A$22)) -> 10.312763 | G24: =DEGREES(ASIN((1235-($C$23-G22/2))/$A$22)) -> 10.418666 | H24: =DEGREES(ASIN((1235-($C$23-H22/2))/$A$22)) -> 10.577587 | I24: =DEGREES(ASIN((1235-($C$23-I22/2))/$A$22)) -> 10.577587
A25: А/В | B25: дП | D25: =(3*$A$19)*(SQRT(((1/D21)-(1/($C$3/2)))*$A$19)) -> 0.88244905 | E25: =(3*$A$19)*(SQRT(((1/E21)-(1/($C$3/2)))*$A$19)) -> 3.3875272 | F25: =(3*$A$19)*(SQRT(((1/F21)-(1/($C$3/2)))*$A$19)) -> 5.1245963 | G25: =(3*$A$19)*(SQRT(((1/G21)-(1/($C$3/2)))*$A$19)) -> 6.721403 | H25: =(3*$A$19)*(SQRT(((1/H21)-(1/($C$3/2)))*$A$19)) -> 8.315938 | I25: =(3*$A$19)*(SQRT(((1/I21)-(1/($C$3/2)))*$A$19)) -> 9.9597894
A26: =E15/E4 -> 1.2600828 | B26: П | D26: =$C$3*PI()-D25 -> 771.2285 | E26: =$C$3*PI()-E25 -> 768.72342 | F26: =$C$3*PI()-F25 -> 766.98635 | G26: =$C$3*PI()-G25 -> 765.38954 | H26: =$C$3*PI()-H25 -> 763.79501 | I26: =$C$3*PI()-I25 -> 762.15115
A27: =F15/F5 -> 1.0398635 | B27: ПR | D27: =(2*D21*PI())/2 -> 378.20149 | E27: =(2*E21*PI())/4 -> 147.7982 | F27: =(2*F21*PI())/4 -> 113.52326 | G27: =(2*G21*PI())/4 -> 87.549715 | H27: =(2*H21*PI())/4 -> 67.86696 | I27: =(2*I21*PI())/4 -> 52.951369
A28: =G15/G5 -> 1.0318514 | B28: ПдР | D28: =((D26-D27)/(D15/D5))/2 -> 188.67712 | E28: =((E26-E27)/A26)/2 -> 246.3827 | F28: =((F26-F27)/A27)/2 -> 314.20619 | G28: =((G26-G27)/A28)/2 -> 328.45806 | H28: =((H26-H27)/A29)/2 -> 346.38072 | I28: =((I26-I27)/A30)/2 -> 354.59989 | J28: =I28+I21*2 -> 422.01967
A29: =H15/H5 -> 1.004571 | B29: Дк | D29: =D8+D3/2 -> 531.5 | E29: =((E6-SQRT(E6^2-(E28^2/4)))+E8)-(0.75*(((E6-SQRT(E6^2-(E28^2/4)))+E8)-E8)) -> 551.19573 | F29: =((F6-SQRT(F6^2-(F28^2/4)))+F8)-(0.75*(((F6-SQRT(F6^2-(F28^2/4)))+F8)-F8)) -> 567.58209 | G29: =((G6-SQRT(G6^2-(G28^2/4)))+G8)-(0.75*(((G6-SQRT(G6^2-(G28^2/4)))+G8)-G8)) -> 578.12464 | H29: =((H6-SQRT(H6^2-(H28^2/4)))+H8)-(0.75*(((H6-SQRT(H6^2-(H28^2/4)))+H8)-H8)) -> 587.53571 | I29: =((I6-SQRT(I6^2-(I28^2/4)))+I8)-(0.75*(((I6-SQRT(I6^2-(I28^2/4)))+I8)-I8)) -> 589.00393
A30: =I15/I5 -> 1 | B30: Кс | D30: 1 | E30: =1/((E29/$D$29)*(1+0.022*((2-1)/6))) -> 0.96074453 | F30: =1/((F29/$D$29)*(1+0.022*((2-1)/6))) -> 0.93300739 | G30: =1/((G29/$D$29)*(1+0.022*((2-1)/6)))*0.847 -> 0.77584631 | H30: =1/((H29/$D$29)*(1+0.022*((2-1)/6))) -> 0.90132103 | I30: =1/((I29/$D$29)*(1+0.022*((2-1)/6))) -> 0.89907428
B31: Тк | D31: =IF(D3<=0,0.5*(D8+(D5-D3)-(D12+2*135)),0.5*(D8+D5-(D12+2*135))) -> 99.885273 | E31: =IF(E3<=0,0.5*(E8+(E5-E3)-(E12+2*135)),0.5*(E8+E5-(E12+2*135))) -> 102.88527 | F31: =0.5*(F8+F5-(F12+2*135)) -> 110.38527 | G31: =0.5*(G8+G5-(G12+2*135)) -> 113.38527 | H31: =0.5*(H8+H5-(H12+2*135)) -> 117.88527 | I31: =0.5*(I8+I5-(I12+2*135)) -> 117.88527
B32: База | D32: =D11-D31 -> 41.114727 | E32: =E11-E31 -> 38.114727 | F32: =F11-F31 -> 30.614727 | G32: =G11-G31 -> 27.614727 | H32: =H11-H31 -> 23.114727 | I32: =I11-I31 -> 23.114727 | J32: 700
B33: H | D33: =(($D$12-80)-(60+A13))/2 -> 27.5 | E33: =((E12-80)-(60+A14))/2 -> 22.5 | F33: =((F12-80)-(60+A15))/2 -> 17.5 | G33: =((G12-80)-(60+A16))/2 -> 17.5 | H33: =((H12-80)-(60+A17))/2 -> 12.5 | I33: =((I12-80)-(60+A18))/2 -> 7.5 | J33: =((I8/1000)*PI()*J32) -> 1295.2787
B34: Lд | D34: =IF(D3<=0,0,SQRT((D29/2)*D3)) -> 36.452023 | E34: =IF(E3<=0,0,SQRT((E29/2)*E3)) -> 59.856263 | F34: =SQRT((F29/2)*F3) -> 23.823981 | G34: =SQRT((G29/2)*G3) -> 41.645815 | H34: =SQRT((H29/2)*H3) -> 17.139657 | I34: =SQRT((I29/2)*I3) -> 24.269403
B35: σв | C35: 40 | D35: =IF(D34=0,C35,(((D3*100/$J$3)*($J$35-$C$35))/100)+C35) -> 42.586207 | E35: =IF(E34=0,C35,(((E3*100/$J$3)*($J$35-$C$35))/100)+D35) -> 49.310345 | F35: =IF(F34=0,C35,(((F3*100/$J$3)*($J$35-$C$35))/100)+E35) -> 50.344828 | G35: =(((G3*100/$J$3)*($J$35-$C$35))/100)+F35 -> 53.448276 | H35: =(((H3*100/$J$3)*($J$35-$C$35))/100)+G35 -> 53.965517 | I35: =(((I3*100/$J$3)*($J$35-$C$35))/100)+H35 -> 55 | J35: 55
B36: Рпр | D36: =((2*D35*$A$19*D34)*0.8)/1000 -> 19.870124 | E36: =((2*E35*$A$19*E34)*0.8)/1000 -> 37.779622 | F36: =((2*F35*$A$19*F34)*0.8)/1000 -> 15.352502 | G36: =((2*G35*$A$19*G34)*0.8)/1000 -> 28.491482 | H36: =((2*H35*$A$19*H34)*0.8)/1000 -> 11.839366 | I36: =((2*I35*$A$19*I34)*0.8)/1000 -> 17.08566
B37: Мпр | D37: =IF(D3<=0,0,(3.615*D35*D29*$A$19^2*LOG10((C3/2)/D21))/1000) -> 46.745583 | E37: =IF(E3<=0,0,IF(D3<=0,(3.615*D35*D29*$A$19^2*LOG10((B3/2)/E21))/1000,(0.5*E35*E29*(7.23*$A$19^2*LOG10(D21/E21)+$A$19*(D26-E26)))/1000)) -> 945.34648 | F37: =IF(F3<=0,0,IF(E3<=0,(3.615*E35*E29*$A$19^2*LOG10((C3/2)/F21))/1000,(0.5*F35*F29*(7.23*$A$19^2*LOG10(E21/F21)+$A$19*(E26-F26)))/1000)) -> 956.07061 | G37: =IF(G3<=0,0,IF(F3<=0,(3.615*F35*F29*$A$19^2*LOG10((D3/2)/G21))/1000,(0.5*G35*G29*(7.23*$A$19^2*LOG10(F21/G21)+$A$19*(F26-G26)))/1000)) -> 1003.983 | H37: =(0.5*H35*H29*(7.23*$A$19^2*LOG10(G21/H21)+$A$19*(G26-H26)))/1000 -> 1013.5261 | I37: =(0.5*I35*I29*(7.23*$A$19^2*LOG10(H21/I21)+$A$19*(H26-I26)))/1000 -> 1020.8272 | K37: =(0.5*G35*G29*(7.23*$A$19^2+$A$19*(F26-G26)))/1000 -> 7346.3335
B39: Р | D39: =((2*D37*D34)/(3.615*$A$19*LOG10((C3/2)/D21))/1000) -> 13.201213 | E39: =4*((4*E37*E34)/(7.23*$A$19^2*LOG10(D21/E21)))/1000 -> 18.281877 | F39: =4*((4*F37*F34)/(7.23*$A$19^2*LOG10(E21/F21)))/1000 -> 6.8735478 | G39: =4*((4*G37*G34)/(7.23*$A$19^2*LOG10(F21/G21)))/1000 -> 12.813694 | H39: =4*((4*H37*H34)/(7.23*$A$19^2*LOG10(G21/H21)))/1000 -> 5.4312281 | I39: =4*((4*I37*I34)/(7.23*$A$19^2*LOG10(H21/I21)))/1000 -> 7.9482224
B40: МпрП | D40: =D36*D34*0.16 -> 115.88899 | E40: =E36*E34*0.16 -> 361.81552 | F40: =F36*F34*0.16 -> 58.521236 | G40: =G36*G34*0.16 -> 189.84816 | H40: =H36*H34*0.16 -> 32.467628 | I40: =I36*I34*0.16 -> 66.345403
B41: Rp | D41: =((D36*(D21*2))/(2.65*$A$19*(1-($A$19/(D21*2))))) -> 233.42287 | E41: =((E36*(E21*2))/(2.65*$A$19*(1-($A$19/(E21*2))))) -> 350.24153 | F41: =((F36*(F21*2))/(2.65*$A$19*(1-($A$19/(F21*2))))) -> 110.8067 | G41: =((G36*(G21*2))/(2.65*$A$19*(1-($A$19/(G21*2))))) -> 161.39388 | H41: =((H36*(H21*2))/(2.65*$A$19*(1-($A$19/(H21*2))))) -> 53.180595 | I41: =((I36*(I21*2))/(2.65*$A$19*(1-($A$19/(I21*2))))) -> 61.650911 | J41: =SUM(D41:I41) -> 970.69649
...

Sheet ВНИТИ
G1: Программа №4 с К/К | O1: ГВ | P1: 590 | R1: ст20 | S1: 450МПА | T1: 45кг/м
O2: ВВ | P2: 460
F3: Для расчётов калибровок по заданной схеме. | Q3: =NOW() -> 46288.744
B4: z 2-5, | C4: S, | D4: rн, | E4: r`н, | F4: rн/S, | G4: Дз, | H4: Да, | I4: Дв, | J4: А, | K4: В, | L4: δ, мм | O4: Д0а, | P4: Д0в, | Q4: α1, | R4: sт, | S4: V,
B5: шт | C5: мм | D5: мм | E5: мм | G5: мм | H5: мм | I5: мм | J5: мм | K5: мм | L5: к.1-к.2 | M5: к.3-к.4 | N5: к.5-к.6 | O5: мм | P5: мм | Q5: град | R5: кг/мм² | S5: м/мин
B6: 4 | C6: 12 | D6: 25.5 | E6: =(2.35-0.007*(ATAN(0.5*(1/('Расчётные данные'!D12*(1/D6-1/'Расчётные данные'!E12))))*180/PI()))*D6/1.72 -> 29.153558 | F6: =D6/C6 -> 2.125 | G6: =((((SQRT((1/ВНИТИ!E6-1/'Расчётные данные'!E12)*'Расчётные данные'!D12))*'Расчётные данные'!D12*3)+(2*('Расчётные данные'!B12+'Расчётные данные'!C12)-ВНИТИ!E6*1.72))/PI()) -> 193.96824 | H6: =P1 -> 590 | I6: =P2 -> 460 | J6: 160 | K6: 160 | L6: 15 | M6: 10 | N6: 5 | O6: =P1+K6 -> 750 | P6: =P2+J6 -> 620 | Q6: 8 | R6: 40 | S6: 5
B8: Схема профилирования | D8: Клеть | E8: Валки | F8: DПi/П, | G8: Пi, | H8: DПи, | I8: ri, | J8: Ria,мм | K8: Ai,мм | L8: Промежуточная величина, мм | N8: Коэфф. скорости | O8: ai,мм | P8: Ha,мм | Q8: A`,мм | R8: Да,мм
F9: % | G9: мм | H9: мм | I9: мм | J9: Riв,мм | K9: Bi,мм | O9: вi,мм | P9: Hв,мм | Q9: B`,мм | R9: Дэ,мм
D10: 1 | E10: A | F10: 0 | G10: =G6*PI() -> 609.3692 | H10: 0 | I10: ='Расчётные данные'!G205 -> 94.073446 | J10: ='Расчётные данные'!E205 -> 154.2769 | K10: ----- | L10: ----- | O10: ='Расчётные данные'!I205 -> 133.84481 | P10: ='Расчётные данные'!B166 -> 15.270593 | Q10: ='Расчётные данные'!F205 -> 197.41084 | R10: min | S10: ='Расчётные данные'!B189 -> 561.4962
R11: max | S11: ='Расчётные данные'!B186 -> 592.03739
D12: зада- | E12: B | J12: ----- | K12: ----- | O12: ----- | P12: ----- | Q12: ='Расчётные данные'!B205 -> 188.5038 | R12: -----
D13: ющая
C14: Формирующие | D14: 2 | E14: A | F14: ='Расчётные данные'!D27 -> 1.2696541 | G14: ='Расчётные данные'!C27 -> 601.63232 | H14: ='Расчётные данные'!H27 -> 7.7368813 | I14: ='Расчётные данные'!E27 -> 70.621738 | J14: ='Расчётные данные'!B61 -> 171.50627 | K14: ='Расчётные данные'!B102 -> 180.46783 | L14: a= | M14: ='Расчётные данные'!B114 -> 71.406144 | N14: ='Расчётные данные'!C289 -> 0.99055552 | O14: ='Расчётные данные'!B150 -> 133.2261 | P14: ='Расчётные данные'!C166 -> 13.464811 | Q14: ='Расчётные данные'!B126 -> 184.63662 | R14: min | S14: ='Расчётные данные'!C189 -> 565.72648
L15: b= | M15: ='Расчётные данные'!B117 -> 79.369514 | R15: max | S15: ='Расчётные данные'!C186 -> 592.6561
E16: B | J16: ='Расчётные данные'!B64 -> 163.72446 | K16: ='Расчётные данные'!B99 -> 180.42415 | L16: x= | M16: ='Расчётные данные'!B134 -> 73.931385 | O16: ='Расчётные данные'!B161 -> 136.51422 | P16: ='Расчётные данные'!C169 -> 14.906901 | Q16: ='Расчётные данные'!B123 -> 184.27352 | R16: min | S16: ='Расчётные данные'!B197 -> 435.36338
L17: y= | M17: ='Расчётные данные'!B137 -> 75.383685 | R17: max | S17: ='Расчётные данные'!B194 -> 465.17718
D18: 3 | E18: A | F18: ='Расчётные данные'!D30 -> 1.9369144 | G18: ='Расчётные данные'!C30 -> 597.56624 | H18: ='Расчётные данные'!H30 -> 4.0660783 | I18: ='Расчётные данные'!E30 -> 51.897779 | J18: ='Расчётные данные'!C61 -> 303.29091 | K18: ='Расчётные данные'!C102 -> 171.46034 | L18: a= | M18: ='Расчётные данные'!C114 -> 188.10246 | N18: ='Расчётные данные'!D289 -> 0.9805848 | O18: ='Расчётные данные'!C150 -> 142.79459 | P18: ='Расчётные данные'!D166 -> 8.5235402 | Q18: ='Расчётные данные'!C126 -> 176.58036 | R18: min | S18: ='Расчётные данные'!D189 -> 574.01795
L19: b= | M19: ='Расчётные данные'!C117 -> 215.29988 | R19: max | S19: ='Расчётные данные'!D186 -> 591.06503
E20: B | J20: ='Расчётные данные'!C64 -> 276.39264 | K20: ='Расчётные данные'!C99 -> 171.4081 | L20: x= | M20: ='Расчётные данные'!C134 -> 77.043296 | O20: ='Расчётные данные'!C161 -> 145.0631 | P20: ='Расчётные данные'!D169 -> 9.6866858 | Q20: ='Расчётные данные'!C123 -> 175.98205 | R20: min | S20: ='Расчётные данные'!C197 -> 443.41964
L21: y= | M21: ='Расчётные данные'!C137 -> 78.042418 | R21: max | S21: ='Расчётные данные'!C194 -> 462.79301
D22: 4 | E22: A | F22: ='Расчётные данные'!D33 -> 2.5557895 | G22: ='Расчётные данные'!C33 -> 593.79501 | H22: ='Расчётные данные'!H33 -> 3.7712342 | I22: ='Расчётные данные'!E33 -> 38.599032 | J22: ='Расчётные данные'!D61 -> 536.33825 | K22: ='Расчётные данные'!D102 -> 164.90174 | L22: a= | M22: ='Расчётные данные'!D114 -> 381.89303 | N22: ='Расчётные данные'!E289 -> 0.82286668 | O22: ='Расчётные данные'!D150 -> 143.65223 | P22: ='Расчётные данные'!E166 -> 4.8312153 | Q22: ='Расчётные данные'!D126 -> 169.40247 | R22: min | S22: ='Расчётные данные'!E189 -> 581.26741
L23: b= | M23: ='Расчётные данные'!D117 -> 451.97196 | R23: max | S23: ='Расчётные данные'!E186 -> 590.92984
E24: B | J24: ='Расчётные данные'!D64 -> 466.59427 | K24: ='Расчётные данные'!D99 -> 164.86163 | L24: x= | M24: ='Расчётные данные'!D134 -> 78.022921 | O24: ='Расчётные данные'!D161 -> 145.17467 | P24: ='Расчётные данные'!E169 -> 5.6807302 | Q24: ='Расчётные данные'!D123 -> 168.73259 | R24: min | S24: ='Расчётные данные'!D197 -> 450.59753
L25: y= | M25: ='Расчётные данные'!D137 -> 78.660823 | R25: max | S25: ='Расчётные данные'!D194 -> 461.95899
D26: 5 | E26: A | F26: ='Расчётные данные'!D36 -> 3.1697808 | G26: ='Расчётные данные'!C36 -> 590.05354 | H26: ='Расчётные данные'!H36 -> 3.7414744 | I26: ='Расчётные данные'!E36 -> 29.153558 | J26: ='Расчётные данные'!E61 -> 948.45811 | K26: ='Расчётные данные'!E102 -> 159.97432 | L26: a= | M26: ='Расчётные данные'!E114 -> 705.99295 | N26: ='Расчётные данные'!F289 -> 0.96322245 | O26: ='Расчётные данные'!E150 -> 149.0595 | P26: ='Расчётные данные'!F166 -> 2.9328046 | Q26: ='Расчётные данные'!E126 -> 163.38317 | R26: min | S26: ='Расчётные данные'!F189 -> 587.23697
L27: b= | M27: ='Расчётные данные'!E117 -> 867.0766 | R27: max | S27: ='Расчётные данные'!F186 -> 593.10258
E28: B | J28: ='Расчётные данные'!E64 -> 787.68453 | K28: ='Расчётные данные'!E99 -> 159.95 | L28: x= | M28: ='Расчётные данные'!E134 -> 77.801678 | O28: ='Расчётные данные'!E161 -> 149.92837 | P28: ='Расчётные данные'!F169 -> 3.5752967 | Q28: ='Расчётные данные'!E123 -> 162.76303 | R28: min | S28: ='Расчётные данные'!E197 -> 456.61683
L29: y= | M29: ='Расчётные данные'!E137 -> 78.185107 | R29: max | S29: ='Расчётные данные'!E194 -> 463.76742
D30: 6 | E30: A | F30: ----- | G30: ='Расчётные данные'!C39 -> 586.29235 | H30: ----- | I30: =D6 -> 25.5 | J30: Q | K30: ----- | L30: ----- | N30: ='Расчётные данные'!G289 -> 0.9611056 | O30: =J6-(N6*1.4142) -> 152.929 | P30: ----- | Q30: =J6 -> 160 | R30: =H6 -> 590
D32: калиб- | E32: B | J32: Q | K32: ----- | O32: =K6-(N6*1.4142) -> 152.929 | P32: ----- | Q32: =K6 -> 160 | R32: =I6 -> 460
D33: рующая
D35: Z-количество формирующих клетей
D36: Д0а,Д0в-межосевое расстояние
B38: Клеть | C38: L | D38: Р | E38: a | F38: Мпр. | G38: n | H38: Nдв. | I38: L- | J38: Длинна очага деформации (мм). | U38: =SQRT(U40/(U41/2)) -> 0.13951295 | V38: =SQRT(V40/(V41/2)) -> 0.12229148 | W38: =SQRT(W40/(W41/2)) -> 0.16996834 | X38: =SQRT(X40/(X41/2)) -> 0.15793549 | Y38: =SQRT(Y40/(Y41/2)) -> 0.1425869 | Z38: =SQRT(Z40/(Z41/2)) -> 0.096779159
C39: мм | D39: тонн | E39: град. | F39: кг*м | G39: об./мин | H39: кВч | I39: Р- | J39: Давление металла на валки (т). | U39: =DEGREES(U38) -> 7.9935031 | V39: =DEGREES(V38) -> 7.0067855 | W39: =DEGREES(W38) -> 9.7384687 | X39: =DEGREES(X38) -> 9.0490371 | Y39: =DEGREES(Y38) -> 8.1696274 | Z39: =DEGREES(Z38) -> 5.5450374
B40: 1 зада- | C40: ='Расчётные данные'!B223 -> 39.167995 | D40: ='Расчётные данные'!B228 -> 30.08102 | E40: ='Расчётные данные'!B234 -> 8 | F40: ='Расчётные данные'!B240 -> 154.72302 | G40: ='Расчётные данные'!B246 -> 2.8344794 | H40: ='Расчётные данные'!B252 -> 0.68888722 | I40: a- | J40: Угол захвата (град.). | U40: =G6-Q12 -> 5.4644424 | V40: =Q12-Q16 -> 4.2302779 | W40: =Q16-Q20 -> 8.2914704 | X40: =Q20-Q24 -> 7.2494564 | Y40: =Q24-Q28 -> 5.9695642 | Z40: =Q28-Q32 -> 2.7630307
B41: ющая | I41: Мпр.- | J41: Момент прокатки (кг*м). | U41: =S10 -> 561.4962 | V41: =S14 -> 565.72648 | W41: =S18 -> 574.01795 | X41: =S22 -> 581.26741 | Y41: =S26 -> 587.23697 | Z41: =R30 -> 590
B42: 2 | C42: ='Расчётные данные'!C223 -> 35.001001 | D42: ='Расчётные данные'!C228 -> 33.600961 | E42: ='Расчётные данные'!C234 -> 6.9290828 | F42: ='Расчётные данные'!C240 -> 2577.3068 | G42: ='Расчётные данные'!C246 -> 2.7478822 | H42: ='Расчётные данные'!C252 -> 11.124592 | I42: n- | J42: Число оборотов валков (об./мин).
I43: Nдв.- | J43: Мощность двигателя (кВт).
B44: 3 | C44: ='Расчётные данные'!D223 -> 49.143288 | D44: ='Расчётные данные'!D228 -> 47.177557 | E44: ='Расчётные данные'!D234 -> 9.6784642 | F44: ='Расчётные данные'!D240 -> 2191.3347 | G44: ='Расчётные данные'!D246 -> 2.7320791 | H44: ='Расчётные данные'!D252 -> 9.4042001 | U44: =SQRT(U46/(U47/2)) -> 0.058722022 | V44: =SQRT(V46/(V47/2)) -> 0.08304548 | W44: =SQRT(W46/(W47/2)) -> 0.10170953 | X44: =SQRT(X46/(X47/2)) -> 0.11744404 | Y44: =SQRT(Y46/(Y47/2)) -> 0.13130643 | Z44: =SQRT(Z46/(Z47/2)) -> 0.14383899 | AA44: =SQRT(AA46/(AA47/2)) -> 0.15536387 | AB44: =SQRT(AB46/(AB47/2)) -> 0.16609096 | ... AD44: =SQRT(AD46/(AD47/2)) -> 0.18569534
...

Sheet Расчётные данные
D3: Задающие параметры:
C5: Д3 | F5: Дв | H5: d3-4 | I5: d5-6
C6: =ВНИТИ!G6 -> 193.96824 | F6: =ВНИТИ!I6 -> 460 | H6: =ВНИТИ!M6 -> 10 | I6: =ВНИТИ!N6 -> 5
B9: РАСЧЁТ ФАКТИЧЕСКОГО РАДИУСА ЗАКРУГЛЕНИЯ И ДИАМЕТРА ЗАГОТОВКИ:
